Workbook

Sheet Данные
A1: тип_респондента | B1: пол | C1: семейное_положение | D1: дети | E1: частота_покупки | F1: цена_слишком_низкая | G1: цена_выгодная_сделка | H1: цена_завышенная_но_куплю | I1: цена_слишком_высокая | J1: проживание | K1: доля_обязательных_платежей
A2: Людмила Петровна | B2: женский | C2: состоит в браке | D2: дети есть, но они уже большие (старше 18) | E2: одну пару раз в два года или реже | F2: 600 | G2: 800 | H2: 2400 | I2: 3500 | J2: город с населением до 500 тыс. человек | K2: от 50% до 75%
A3: Илья | B3: мужской | C3: в гражданском браке | D3: нет детей | E3: две-три пары в год | F3: 1500 | G3: 3800 | H3: 8700 | I3: 16500 | J3: город-миллионник | K3: менее 25%
A4: Михаил | B4: мужской | C4: состоит в браке | D4: один ребенок | E4: обычно одну пару в год | F4: 2000 | G4: 4000 | H4: 9900 | I4: 20000 | J4: город-миллионник | K4: от 25% до 50%
A5: Руслан | B5: мужской | C5: состоит в браке | D5: один ребенок | E5: две-три пары в год | F5: 800 | G5: 1800 | H5: 2700 | I5: 4500 | J5: город с населением до 500 тыс. человек | K5: от 50% до 75%
A6: Алексей | B6: мужской | C6: состоит в браке | D6: нет детей | E6: обычно одну пару в год | F6: 1800 | G6: 3800 | H6: 8400 | I6: 14500 | J6: большой город с населением несколько миллионов | K6: менее 25%
A7: Алексей | B7: мужской | C7: состоит в браке | D7: один ребенок | E7: обычно одну пару в год | F7: 1400 | G7: 4600 | H7: 7500 | I7: 13500 | J7: большой город с населением несколько миллионов | K7: менее 25%
A8: Екатерина | B8: женский | C8: состоит в браке | D8: есть двое и более | E8: обычно одну пару в год | F8: 700 | G8: 2400 | H8: 4200 | I8: 6000 | J8: город с населением до 500 тыс. человек | K8: от 50% до 75%
A9: Илья | B9: мужской | C9: в гражданском браке | D9: нет детей | E9: две-три пары в год | F9: 2000 | G9: 3600 | H9: 8400 | I9: 13000 | J9: город-миллионник | K9: менее 25%
A10: Руслан | B10: мужской | C10: состоит в браке | D10: есть двое и более | E10: две-три пары в год | F10: 800 | G10: 1800 | H10: 2700 | I10: 4000 | J10: город с населением до 500 тыс. человек | K10: от 25% до 50%
A11: Михаил | B11: мужской | C11: состоит в браке | D11: есть двое и более | E11: обычно одну пару в год | F11: 1900 | G11: 4400 | H11: 9600 | I11: 18000 | J11: город-миллионник | K11: от 25% до 50%
A12: Екатерина | B12: женский | C12: состоит в браке | D12: есть двое и более | E12: обычно одну пару в год | F12: 800 | G12: 2200 | H12: 4800 | I12: 7500 | J12: город-миллионник | K12: от 50% до 75%
A13: Алиса | B13: женский | C13: в гражданском браке | D13: нет детей | E13: обычно одну пару в год | F13: 2000 | G13: 6000 | H13: 14100 | I13: 24500 | J13: большой город с населением несколько миллионов | K13: менее 25%
... A1001: Кристина | B1001: женский | C1001: в гражданском браке | D1001: нет детей | E1001: две-три пары в год | F1001: 1300 | G1001: 3000 | H1001: 8700 | I1001: 12000 | J1001: город-миллионник | K1001: от 25% до 50%

Sheet результат
Q1: A | R1: B | S1: C | T1: D | U1: E | V1: J | W1: K
Q2: тип респондента | R2: пол | S2: семейное положение | T2: дети | U2: частота покупки | V2: проживание | W2: доля обязательных платежей
Q3: Q4:Q13 | R3: R4:R5 | S3: S4:S6 | T3: T4:T7 | U3: U4:U6 | V3: V4:V7 | W3: W4:W7
Q4: Людмила Петровна | R4: женский | S4: состоит в браке | T4: дети есть, но они уже большие (старше 18) | U4: одну пару раз в два года или реже | V4: город с населением до 500 тыс. человек | W4: от 50% до 75%
Q5: Илья | R5: мужской | S5: в гражданском браке | T5: нет детей | U5: две-три пары в год | V5: город-миллионник | W5: менее 25%
Q6: Михаил | S6: не в отношениях | T6: один ребенок | U6: обычно одну пару в год | V6: большой город с населением несколько миллионов | W6: от 25% до 50%
Q7: Руслан | T7: есть двое и более | V7: небольшой поселок / город с населением менее 100 тыс. человек
Q8: Алексей
Q9: Екатерина
Q10: Алиса
Q11: Данил
Q12: Кристина
Q13: Арина
B15: 1 Группа
B16: Тип группы | C16: Значение | D16: Выборка | F16: столб. | G16: строка | Q16: =COUNTIF(INDIRECT("Данные!"&Q$1&":"&Q$1),[1]результат!Q4) -> 56 | R16: =COUNTIF(INDIRECT("Данные!"&R$1&":"&R$1),[1]результат!R4) -> 364 | S16: =COUNTIF(INDIRECT("Данные!"&S$1&":"&S$1),[1]результат!S4) -> 577 | T16: =COUNTIF(INDIRECT("Данные!"&T$1&":"&T$1),[1]результат!T4) -> 56 | U16: =COUNTIF(INDIRECT("Данные!"&U$1&":"&U$1),[1]результат!U4) -> 56 | V16: =COUNTIF(INDIRECT("Данные!"&V$1&":"&V$1),[1]результат!V4) -> 230 | W16: =COUNTIF(INDIRECT("Данные!"&W$1&":"&W$1),[1]результат!W4) -> 114
A17: Выберите свою группу и значение >> | B17: пол | C17: мужской | D17: =INDEX($Q$16:$W$25,G17,F17)&" респондентов" -> 636 респондентов | F17: =MATCH(B17,$Q$2:$W$2,0) -> 2 | G17: =MATCH(C17,INDIRECT(HLOOKUP(B17,$Q$2:$W$3,2,0)),0) -> 2 | Q17: =COUNTIF(INDIRECT("Данные!"&Q$1&":"&Q$1),[1]результат!Q5) -> 161 | R17: =COUNTIF(INDIRECT("Данные!"&R$1&":"&R$1),[1]результат!R5) -> 636 | S17: =COUNTIF(INDIRECT("Данные!"&S$1&":"&S$1),[1]результат!S5) -> 184 | T17: =COUNTIF(INDIRECT("Данные!"&T$1&":"&T$1),[1]результат!T5) -> 493 | U17: =COUNTIF(INDIRECT("Данные!"&U$1&":"&U$1),[1]результат!U5) -> 435 | V17: =COUNTIF(INDIRECT("Данные!"&V$1&":"&V$1),[1]результат!V5) -> 550 | W17: =COUNTIF(INDIRECT("Данные!"&W$1&":"&W$1),[1]результат!W5) -> 495
A18: (из списка) | Q18: =COUNTIF(INDIRECT("Данные!"&Q$1&":"&Q$1),[1]результат!Q6) -> 106 | S18: =COUNTIF(INDIRECT("Данные!"&S$1&":"&S$1),[1]результат!S6) -> 239 | T18: =COUNTIF(INDIRECT("Данные!"&T$1&":"&T$1),[1]результат!T6) -> 223 | U18: =COUNTIF(INDIRECT("Данные!"&U$1&":"&U$1),[1]результат!U6) -> 509 | V18: =COUNTIF(INDIRECT("Данные!"&V$1&":"&V$1),[1]результат!V6) -> 190 | W18: =COUNTIF(INDIRECT("Данные!"&W$1&":"&W$1),[1]результат!W6) -> 391
B19: PMC | C19: PME | F19: График | Q19: =COUNTIF(INDIRECT("Данные!"&Q$1&":"&Q$1),[1]результат!Q7) -> 121 | T19: =COUNTIF(INDIRECT("Данные!"&T$1&":"&T$1),[1]результат!T7) -> 228 | V19: =COUNTIF(INDIRECT("Данные!"&V$1&":"&V$1),[1]результат!V7) -> 30
A20: Допустимый ценовой диапазон | B20: 2430 | C20: 5150 | Q20: =COUNTIF(INDIRECT("Данные!"&Q$1&":"&Q$1),[1]результат!Q8) -> 152
Q21: =COUNTIF(INDIRECT("Данные!"&Q$1&":"&Q$1),[1]результат!Q9) -> 117
A22: Точка безразличия IPP | B22: 4800 | Q22: =COUNTIF(INDIRECT("Данные!"&Q$1&":"&Q$1),[1]результат!Q10) -> 38
Q23: =COUNTIF(INDIRECT("Данные!"&Q$1&":"&Q$1),[1]результат!Q11) -> 96
Q24: =COUNTIF(INDIRECT("Данные!"&Q$1&":"&Q$1),[1]результат!Q12) -> 104
Q25: =COUNTIF(INDIRECT("Данные!"&Q$1&":"&Q$1),[1]результат!Q13) -> 49
B39: 2 Группа
B40: Тип группы | C40: Значение | D40: Выборка | F40: столб. | G40: строка
A41: Выберите свою группу и значение >> | B41: пол | C41: женский | D41: =INDEX($Q$16:$W$25,G41,F41)&" респондентов" -> 364 респондентов | F41: =MATCH(B41,$Q$2:$W$2,0) -> 2 | G41: =MATCH(C41,INDIRECT(HLOOKUP(B41,$Q$2:$W$3,2,0)),0) -> 1
A42: (из списка)
B43: PMC | C43: PME | F43: График
A44: Допустимый ценовой диапазон | B44: 2300 | C44: 4500
A46: Точка безразличия IPP | B46: 3400
B63: 3 Группа
B64: Тип группы | C64: Значение | D64: Выборка | F64: столб. | G64: строка
A65: Выберите свою группу и значение >> | B65: проживание | C65: город-миллионник | D65: =INDEX($Q$16:$W$25,G65,F65)&" респондентов" -> 550 респондентов | F65: =MATCH(B65,$Q$2:$W$2,0) -> 6 | G65: =MATCH(C65,INDIRECT(HLOOKUP(B65,$Q$2:$W$3,2,0)),0) -> 2
A66: (из списка)
B67: PMC | C67: PME | F67: График
A68: Допустимый ценовой диапазон | B68: 2750 | C68: 5670
B69: PMC нет точки пересечения
A70: Точка безразличия IPP | B70: 4850
B88: 4 Группа
...

Sheet фигня
A1: цена_слишком_низкая | E1: цена_выгодная_сделка | I1: цена_завышенная_но_куплю | M1: цена_слишком_высокая | R1: цена_слишком_низкая | T1: накоп | V1: цена_выгодная_сделка | Z1: цена_завышенная_но_куплю | AD1: цена_слишком_высокая
A2: 2000 | E2: 4000 | I2: 9900 | M2: 20000 | R2: 2400 | S2: =COUNTIF(A:A,R2) -> 5 | T2: =SUM(T1,S2) -> 5 | U2: =T2/MAX(T:T) -> 0.022421525 | V2: 5800 | W2: =COUNTIF(E:E,V2) -> 4 | X2: =SUM(X1,W2) -> 4 | Y2: =X2/MAX(X:X) -> 0.01793722 | Z2: 2400 | AA2: =COUNTIF(I:I,Z2) -> 4 | AB2: =SUM(AB1,AA2) -> 4 | AC2: =AB2/MAX(AB:AB) -> 0.01793722 | AD2: 4000 | AE2: =COUNTIF(M:M,AD2) -> 12 | AF2: =SUM(AF1,AE2) -> 12 | AG2: =AF2/MAX(AF:AF) -> 0.053811659
A3: 800 | E3: 1800 | I3: 2700 | M3: 4500 | R3: 2300 | S3: =COUNTIF(A:A,R3) -> 8 | T3: =SUM(T2,S3) -> 13 | U3: =T3/MAX(T:T) -> 0.058295964 | V3: 5600 | W3: =COUNTIF(E:E,V3) -> 6 | X3: =SUM(X2,W3) -> 10 | Y3: =X3/MAX(X:X) -> 0.044843049 | Z3: 2700 | AA3: =COUNTIF(I:I,Z3) -> 24 | AB3: =SUM(AB2,AA3) -> 28 | AC3: =AB3/MAX(AB:AB) -> 0.12556054 | AD3: 4500 | AE3: =COUNTIF(M:M,AD3) -> 22 | AF3: =SUM(AF2,AE3) -> 34 | AG3: =AF3/MAX(AF:AF) -> 0.15246637
A4: 1400 | E4: 4600 | I4: 7500 | M4: 13500 | R4: 2200 | S4: =COUNTIF(A:A,R4) -> 1 | T4: =SUM(T3,S4) -> 14 | U4: =T4/MAX(T:T) -> 0.062780269 | V4: 5400 | W4: =COUNTIF(E:E,V4) -> 5 | X4: =SUM(X3,W4) -> 15 | Y4: =X4/MAX(X:X) -> 0.067264574 | Z4: 3000 | AA4: =COUNTIF(I:I,Z4) -> 19 | AB4: =SUM(AB3,AA4) -> 47 | AC4: =AB4/MAX(AB:AB) -> 0.21076233 | AD4: 5000 | AE4: =COUNTIF(M:M,AD4) -> 16 | AF4: =SUM(AF3,AE4) -> 50 | AG4: =AF4/MAX(AF:AF) -> 0.22421525
A5: 1300 | E5: 3400 | I5: 9600 | M5: 14000 | R5: 2100 | S5: =COUNTIF(A:A,R5) -> 3 | T5: =SUM(T4,S5) -> 17 | U5: =T5/MAX(T:T) -> 0.076233184 | V5: 5200 | W5: =COUNTIF(E:E,V5) -> 8 | X5: =SUM(X4,W5) -> 23 | Y5: =X5/MAX(X:X) -> 0.10313901 | Z5: 3300 | AA5: =COUNTIF(I:I,Z5) -> 21 | AB5: =SUM(AB4,AA5) -> 68 | AC5: =AB5/MAX(AB:AB) -> 0.30493274 | AD5: 5500 | AE5: =COUNTIF(M:M,AD5) -> 10 | AF5: =SUM(AF4,AE5) -> 60 | AG5: =AF5/MAX(AF:AF) -> 0.2690583
A6: 1100 | E6: 5000 | I6: 7200 | M6: 12500 | R6: 2000 | S6: =COUNTIF(A:A,R6) -> 13 | T6: =SUM(T5,S6) -> 30 | U6: =T6/MAX(T:T) -> 0.13452915 | V6: 5000 | W6: =COUNTIF(E:E,V6) -> 16 | X6: =SUM(X5,W6) -> 39 | Y6: =X6/MAX(X:X) -> 0.17488789 | Z6: 3600 | AA6: =COUNTIF(I:I,Z6) -> 1 | AB6: =SUM(AB5,AA6) -> 69 | AC6: =AB6/MAX(AB:AB) -> 0.30941704 | AD6: 6000 | AE6: =COUNTIF(M:M,AD6) -> 9 | AF6: =SUM(AF5,AE6) -> 69 | AG6: =AF6/MAX(AF:AF) -> 0.30941704
A7: 1800 | E7: 5000 | I7: 8100 | M7: 14000 | R7: 1900 | S7: =COUNTIF(A:A,R7) -> 10 | T7: =SUM(T6,S7) -> 40 | U7: =T7/MAX(T:T) -> 0.1793722 | V7: 4800 | W7: =COUNTIF(E:E,V7) -> 11 | X7: =SUM(X6,W7) -> 50 | Y7: =X7/MAX(X:X) -> 0.22421525 | Z7: 7200 | AA7: =COUNTIF(I:I,Z7) -> 11 | AB7: =SUM(AB6,AA7) -> 80 | AC7: =AB7/MAX(AB:AB) -> 0.35874439 | AD7: 12000 | AE7: =COUNTIF(M:M,AD7) -> 12 | AF7: =SUM(AF6,AE7) -> 81 | AG7: =AF7/MAX(AF:AF) -> 0.3632287
A8: 700 | E8: 1200 | I8: 2700 | M8: 5500 | R8: 1800 | S8: =COUNTIF(A:A,R8) -> 17 | T8: =SUM(T7,S8) -> 57 | U8: =T8/MAX(T:T) -> 0.25560538 | V8: 4600 | W8: =COUNTIF(E:E,V8) -> 15 | X8: =SUM(X7,W8) -> 65 | Y8: =X8/MAX(X:X) -> 0.29147982 | Z8: 7500 | AA8: =COUNTIF(I:I,Z8) -> 7 | AB8: =SUM(AB7,AA8) -> 87 | AC8: =AB8/MAX(AB:AB) -> 0.39013453 | AD8: 12500 | AE8: =COUNTIF(M:M,AD8) -> 22 | AF8: =SUM(AF7,AE8) -> 103 | AG8: =AF8/MAX(AF:AF) -> 0.46188341
A9: 400 | E9: 1800 | I9: 3300 | M9: 5500 | R9: 1700 | S9: =COUNTIF(A:A,R9) -> 16 | T9: =SUM(T8,S9) -> 73 | U9: =T9/MAX(T:T) -> 0.32735426 | V9: 4400 | W9: =COUNTIF(E:E,V9) -> 11 | X9: =SUM(X8,W9) -> 76 | Y9: =X9/MAX(X:X) -> 0.34080717 | Z9: 7800 | AA9: =COUNTIF(I:I,Z9) -> 12 | AB9: =SUM(AB8,AA9) -> 99 | AC9: =AB9/MAX(AB:AB) -> 0.44394619 | AD9: 13000 | AE9: =COUNTIF(M:M,AD9) -> 14 | AF9: =SUM(AF8,AE9) -> 117 | AG9: =AF9/MAX(AF:AF) -> 0.52466368
A10: 400 | E10: 1000 | I10: 3300 | M10: 6000 | R10: 1600 | S10: =COUNTIF(A:A,R10) -> 19 | T10: =SUM(T9,S10) -> 92 | U10: =T10/MAX(T:T) -> 0.41255605 | V10: 4200 | W10: =COUNTIF(E:E,V10) -> 17 | X10: =SUM(X9,W10) -> 93 | Y10: =X10/MAX(X:X) -> 0.41704036 | Z10: 8100 | AA10: =COUNTIF(I:I,Z10) -> 14 | AB10: =SUM(AB9,AA10) -> 113 | AC10: =AB10/MAX(AB:AB) -> 0.50672646 | AD10: 13500 | AE10: =COUNTIF(M:M,AD10) -> 15 | AF10: =SUM(AF9,AE10) -> 132 | AG10: =AF10/MAX(AF:AF) -> 0.59192825
A11: 1000 | E11: 3200 | I11: 7500 | M11: 13000 | R11: 1500 | S11: =COUNTIF(A:A,R11) -> 5 | T11: =SUM(T10,S11) -> 97 | U11: =T11/MAX(T:T) -> 0.43497758 | V11: 4000 | W11: =COUNTIF(E:E,V11) -> 14 | X11: =SUM(X10,W11) -> 107 | Y11: =X11/MAX(X:X) -> 0.47982063 | Z11: 8400 | AA11: =COUNTIF(I:I,Z11) -> 14 | AB11: =SUM(AB10,AA11) -> 127 | AC11: =AB11/MAX(AB:AB) -> 0.56950673 | AD11: 14000 | AE11: =COUNTIF(M:M,AD11) -> 19 | AF11: =SUM(AF10,AE11) -> 151 | AG11: =AF11/MAX(AF:AF) -> 0.67713004
A12: 2000 | E12: 5200 | I12: 9600 | M12: 16000 | R12: 1400 | S12: =COUNTIF(A:A,R12) -> 11 | T12: =SUM(T11,S12) -> 108 | U12: =T12/MAX(T:T) -> 0.48430493 | V12: 3800 | W12: =COUNTIF(E:E,V12) -> 10 | X12: =SUM(X11,W12) -> 117 | Y12: =X12/MAX(X:X) -> 0.52466368 | Z12: 8700 | AA12: =COUNTIF(I:I,Z12) -> 10 | AB12: =SUM(AB11,AA12) -> 137 | AC12: =AB12/MAX(AB:AB) -> 0.61434978 | AD12: 14500 | AE12: =COUNTIF(M:M,AD12) -> 16 | AF12: =SUM(AF11,AE12) -> 167 | AG12: =AF12/MAX(AF:AF) -> 0.74887892
A13: 1800 | E13: 4200 | I13: 7800 | M13: 14500 | R13: 1300 | S13: =COUNTIF(A:A,R13) -> 9 | T13: =SUM(T12,S13) -> 117 | U13: =T13/MAX(T:T) -> 0.52466368 | V13: 3600 | W13: =COUNTIF(E:E,V13) -> 15 | X13: =SUM(X12,W13) -> 132 | Y13: =X13/MAX(X:X) -> 0.59192825 | Z13: 9000 | AA13: =COUNTIF(I:I,Z13) -> 12 | AB13: =SUM(AB12,AA13) -> 149 | AC13: =AB13/MAX(AB:AB) -> 0.66816143 | AD13: 15000 | AE13: =COUNTIF(M:M,AD13) -> 10 | AF13: =SUM(AF12,AE13) -> 177 | AG13: =AF13/MAX(AF:AF) -> 0.79372197
... A21: 2300 | E21: 5600 | I21: 11100 | M21: 19500 | R21: 400 | S21: =COUNTIF(A:A,R21) -> 8 | T21: =SUM(T20,S21) -> 223 | U21: =T21/MAX(T:T) -> 1 | V21: 1000 | W21: =COUNTIF(E:E,V21) -> 10 | X21: =SUM(X20,W21) -> 223 | Y21: =X21/MAX(X:X) -> 1 | Z21: 11400 | AA21: =COUNTIF(I:I,Z21) -> 9 | AB21: =SUM(AB20,AA21) -> 218 | AC21: =AB21/MAX(AB:AB) -> 0.97757848 | AD21: 19000 | AE21: =COUNTIF(M:M,AD21) -> 1 | AF21: =SUM(AF20,AE21) -> 214 | AG21: =AF21/MAX(AF:AF) -> 0.95964126
A22: 1800 | E22: 4200 | I22: 9900 | M22: 14000 | Z22: 11700 | AA22: =COUNTIF(I:I,Z22) -> 4 | AB22: =SUM(AB21,AA22) -> 222 | AC22: =AB22/MAX(AB:AB) -> 0.9955157 | AD22: 19500 | AE22: =COUNTIF(M:M,AD22) -> 6 | AF22: =SUM(AF21,AE22) -> 220 | AG22: =AF22/MAX(AF:AF) -> 0.98654709
A23: 800 | E23: 1000 | I23: 3300 | M23: 4500 | Z23: 12000 | AA23: =COUNTIF(I:I,Z23) -> 1 | AB23: =SUM(AB22,AA23) -> 223 | AC23: =AB23/MAX(AB:AB) -> 1 | AD23: 20000 | AE23: =COUNTIF(M:M,AD23) -> 3 | AF23: =SUM(AF22,AE23) -> 223 | AG23: =AF23/MAX(AF:AF) -> 1
A24: 1200 | E24: 4200 | I24: 9600 | M24: 14500
A25: 1900 | E25: 5000 | I25: 11100 | M25: 16500
A26: 400 | E26: 1400 | I26: 2700 | M26: 5000
A27: 500 | E27: 1000 | I27: 2700 | M27: 5000
A28: 1700 | E28: 3000 | I28: 8100 | M28: 12500
A29: 1900 | E29: 4600 | I29: 9900 | M29: 19500
A30: 1000 | E30: 5000 | I30: 9600 | M30: 14500
A31: 1900 | E31: 4400 | I31: 8700 | M31: 12000
A32: 500 | E32: 1600 | I32: 3000 | M32: 4500
A33: 1200 | E33: 5000 | I33: 9600 | M33: 13000
A34: 1100 | E34: 3600 | I34: 9300 | M34: 13000
A35: 1900 | E35: 4000 | I35: 7800 | M35: 13500
... A224: 1100 | E224: 4800 | I224: 8400 | M224: 13000

Sheet мужики
A1: цена_слишком_низкая | B1: цена_выгодная_сделка | C1: цена_завышенная_но_куплю | D1: цена_слишком_высокая | F1: Названия строк | G1: Количество по полю цена_слишком_низкая2 | I1: Названия строк | J1: Количество по полю цена_выгодная_сделка | L1: Названия строк | M1: Количество по полю цена_завышенная_но_куплю | O1: Названия строк | P1: Количество по полю цена_завышенная_но_куплю
A2: 1500 | B2: 3800 | C2: 8700 | D2: 16500 | F2: 2500 | G2: 0.0047169811 | I2: 6000 | J2: 0.0047169811 | L2: 2400 | M2: 0.0078616352 | O2: 4000 | P2: 0.033018868
A3: 2000 | B3: 4000 | C3: 9900 | D3: 20000 | F3: 2400 | G3: 0.02672956 | I3: 5800 | J3: 0.020440252 | L3: 2700 | M3: 0.081761006 | O3: 4500 | P3: 0.086477987
A4: 800 | B4: 1800 | C4: 2700 | D4: 4500 | F4: 2300 | G4: 0.050314465 | I4: 5600 | J4: 0.04245283 | L4: 3000 | M4: 0.13679245 | O4: 5000 | P4: 0.13050314
A5: 1800 | B5: 3800 | C5: 8400 | D5: 14500 | F5: 2200 | G5: 0.059748428 | I5: 5400 | J5: 0.081761006 | L5: 3300 | M5: 0.18553459 | O5: 5500 | P5: 0.16509434
A6: 1400 | B6: 4600 | C6: 7500 | D6: 13500 | F6: 2100 | G6: 0.075471698 | I6: 5200 | J6: 0.11792453 | L6: 3600 | M6: 0.19025157 | O6: 6000 | P6: 0.19025157
A7: 2000 | B7: 3600 | C7: 8400 | D7: 13000 | F7: 2000 | G7: 0.11006289 | I7: 5000 | J7: 0.18081761 | L7: 3900 | M7: 0.1918239 | O7: 7000 | P7: 0.20283019
A8: 800 | B8: 1800 | C8: 2700 | D8: 4000 | F8: 1900 | G8: 0.16509434 | I8: 4800 | J8: 0.24371069 | L8: 4200 | M8: 0.20440252 | O8: 7500 | P8: 0.22955975
A9: 1900 | B9: 4400 | C9: 9600 | D9: 18000 | F9: 1800 | G9: 0.22798742 | I9: 4600 | J9: 0.29874214 | L9: 4500 | M9: 0.22327044 | O9: 8000 | P9: 0.25471698
A10: 1300 | B10: 5000 | C10: 9900 | D10: 14500 | F10: 1700 | G10: 0.29716981 | I10: 4400 | J10: 0.36477987 | L10: 4800 | M10: 0.24842767 | O10: 8500 | P10: 0.27987421
A11: 1300 | B11: 3400 | C11: 9600 | D11: 14000 | F11: 1600 | G11: 0.36792453 | I11: 4200 | J11: 0.43710692 | L11: 5100 | M11: 0.27672956 | O11: 9000 | P11: 0.30188679
A12: 1100 | B12: 5000 | C12: 7200 | D12: 12500 | F12: 1500 | G12: 0.41823899 | I12: 4000 | J12: 0.49842767 | L12: 5400 | M12: 0.30188679 | O12: 9500 | P12: 0.33176101
A13: 1800 | B13: 5000 | C13: 8100 | D13: 14000 | F13: 1400 | G13: 0.47169811 | I13: 3800 | J13: 0.54874214 | L13: 5700 | M13: 0.3254717 | O13: 10000 | P13: 0.34119497
... A23: 800 | B23: 1600 | C23: 2700 | D23: 5500 | F23: 400 | G23: 1 | I23: 1400 | J23: 0.93238994 | L23: 9600 | M23: 0.74685535 | O23: 16500 | P23: 0.8254717
A24: 1000 | B24: 3200 | C24: 7500 | D24: 13000 | I24: 1200 | J24: 0.97955975 | L24: 9900 | M24: 0.80974843 | O24: 17000 | P24: 0.85691824
A25: 1100 | B25: 3800 | C25: 8700 | D25: 15000 | I25: 1000 | J25: 1 | L25: 10200 | M25: 0.84433962 | O25: 17500 | P25: 0.90251572
A26: 1400 | B26: 4400 | C26: 10500 | D26: 18000 | L26: 10500 | M26: 0.89150943 | O26: 18000 | P26: 0.9418239
A27: 1000 | B27: 2000 | C27: 5400 | D27: 8000 | L27: 10800 | M27: 0.93081761 | O27: 18500 | P27: 0.95440252
A28: 2000 | B28: 5200 | C28: 9600 | D28: 16000 | L28: 11100 | M28: 0.95440252 | O28: 19000 | P28: 0.96855346
A29: 1800 | B29: 4200 | C29: 7800 | D29: 14500 | L29: 11400 | M29: 0.9827044 | O29: 19500 | P29: 0.98899371
A30: 1300 | B30: 4400 | C30: 10800 | D30: 15000 | L30: 11700 | M30: 0.99528302 | O30: 20000 | P30: 1
A31: 700 | B31: 2400 | C31: 5100 | D31: 8500 | L31: 12000 | M31: 1
A32: 800 | B32: 2200 | C32: 6000 | D32: 8500
A33: 600 | B33: 1200 | C33: 3300 | D33: 5000
A34: 600 | B34: 1600 | C34: 3000 | D34: 5000
A35: 1600 | B35: 4000 | C35: 8700 | D35: 14000
A36: 2000 | B36: 5200 | C36: 11700 | D36: 17500
A37: 1900 | B37: 5200 | C37: 8400 | D37: 14000
A38: 1500 | B38: 3600 | C38: 10500 | D38: 13500
A39: 700 | B39: 1400 | C39: 2700 | D39: 5500
A40: 1000 | B40: 4800 | C40: 8700 | D40: 15000
A41: 1600 | B41: 4400 | C41: 8100 | D41: 14000
A42: 900 | B42: 2000 | C42: 4200 | D42: 8000
A43: 800 | B43: 2400 | C43: 6000 | D43: 7500
... A637: 1000 | B637: 3800 | C637: 10200 | D637: 14000

Sheet бабы
A1: цена_слишком_низкая | B1: цена_выгодная_сделка | C1: цена_завышенная_но_куплю | D1: цена_слишком_высокая
A2: 600 | B2: 800 | C2: 2400 | D2: 3500 | G2: Названия строк | H2: Количество по полю цена_слишком_низкая | J2: Названия строк | K2: Количество по полю цена_выгодная_сделка | M2: Названия строк | N2: Количество по полю цена_завышенная_но_куплю | P2: Названия строк | Q2: Количество по полю цена_слишком_высокая
A3: 700 | B3: 2400 | C3: 4200 | D3: 6000 | G3: 3000 | H3: 0.0027472527 | J3: 8000 | K3: 0.0027472527 | M3: 2100 | N3: 0.041208791 | P3: 3500 | Q3: 0.021978022
A4: 800 | B4: 2200 | C4: 4800 | D4: 7500 | G4: 2900 | H4: 0.0082417582 | J4: 7600 | K4: 0.010989011 | M4: 2400 | N4: 0.085164835 | P4: 4000 | Q4: 0.071428571
A5: 2000 | B5: 6000 | C5: 14100 | D5: 24500 | G5: 2800 | H5: 0.016483516 | J5: 7400 | K5: 0.024725275 | M5: 2700 | N5: 0.13736264 | P5: 4500 | Q5: 0.11538462
A6: 1400 | B6: 3800 | C6: 6900 | D6: 11500 | G6: 2700 | H6: 0.019230769 | J6: 7200 | K6: 0.027472527 | M6: 3000 | N6: 0.17582418 | P6: 5000 | Q6: 0.17032967
A7: 600 | B7: 1400 | C7: 3000 | D7: 5000 | G7: 2600 | H7: 0.03021978 | J7: 7000 | K7: 0.035714286 | M7: 3300 | N7: 0.21428571 | P7: 5500 | Q7: 0.1978022
A8: 1400 | B8: 3800 | C8: 6900 | D8: 13000 | G8: 2500 | H8: 0.041208791 | J8: 6800 | K8: 0.049450549 | M8: 3600 | N8: 0.29395604 | P8: 6000 | Q8: 0.29945055
A9: 1400 | B9: 3600 | C9: 7200 | D9: 12500 | G9: 2400 | H9: 0.057692308 | J9: 6600 | K9: 0.057692308 | M9: 3900 | N9: 0.38186813 | P9: 6500 | Q9: 0.39010989
A10: 800 | B10: 1800 | C10: 4800 | D10: 6500 | G10: 2300 | H10: 0.071428571 | J10: 6400 | K10: 0.06043956 | M10: 4200 | N10: 0.46428571 | P10: 7000 | Q10: 0.48901099
A11: 500 | B11: 2000 | C11: 3900 | D11: 7500 | G11: 2200 | H11: 0.082417582 | J11: 6200 | K11: 0.063186813 | M11: 4500 | N11: 0.53846154 | P11: 7500 | Q11: 0.56318681
A12: 2500 | B12: 6600 | C12: 13200 | D12: 22000 | G12: 2100 | H12: 0.090659341 | J12: 6000 | K12: 0.074175824 | M12: 4800 | N12: 0.59615385 | P12: 8000 | Q12: 0.60989011
A13: 900 | B13: 2000 | C13: 3900 | D13: 7000 | G13: 2000 | H13: 0.1043956 | J13: 5800 | K13: 0.076923077 | M13: 5100 | N13: 0.60989011 | P13: 10000 | Q13: 0.62912088
A14: 800 | B14: 3000 | C14: 8400 | D14: 12500 | G14: 1500 | H14: 0.13461538 | J14: 5600 | K14: 0.090659341 | M14: 6000 | N14: 0.61813187 | P14: 10500 | Q14: 0.66758242
... A26: 900 | B26: 2000 | C26: 3900 | D26: 6000 | G26: 300 | H26: 1 | J26: 2400 | K26: 0.45879121 | M26: 12600 | N26: 0.91483516 | P26: 23000 | Q26: 0.95054945
A27: 300 | B27: 1200 | C27: 2400 | D27: 4000 | J27: 2200 | K27: 0.52472527 | M27: 12900 | N27: 0.92582418 | P27: 23500 | Q27: 0.95604396
A28: 800 | B28: 2200 | C28: 4500 | D28: 6500 | J28: 2000 | K28: 0.60164835 | M28: 13200 | N28: 0.93956044 | P28: 24000 | Q28: 0.98351648
A29: 600 | B29: 1000 | C29: 3300 | D29: 6000 | J29: 1800 | K29: 0.68956044 | M29: 13500 | N29: 0.9532967 | P29: 24500 | Q29: 1
A30: 1000 | B30: 3800 | C30: 7200 | D30: 10000 | J30: 1600 | K30: 0.78021978 | M30: 13800 | N30: 0.95879121
A31: 1400 | B31: 3400 | C31: 7800 | D31: 10500 | J31: 1400 | K31: 0.8543956 | M31: 14100 | N31: 0.96978022
A32: 1400 | B32: 3600 | C32: 7200 | D32: 10500 | J32: 1200 | K32: 0.90934066 | M32: 14400 | N32: 0.97252747
A33: 700 | B33: 2000 | C33: 4800 | D33: 6500 | J33: 1000 | K33: 0.96703297 | M33: 14700 | N33: 0.98076923
A34: 600 | B34: 2000 | C34: 3600 | D34: 7500 | J34: 800 | K34: 1 | M34: 15000 | N34: 0.98901099
A35: 800 | B35: 2400 | C35: 4800 | D35: 7500 | M35: 15300 | N35: 0.99175824
A36: 500 | B36: 1600 | C36: 4200 | D36: 6000 | M36: 15900 | N36: 1
A37: 900 | B37: 3800 | C37: 9000 | D37: 13000
A38: 1100 | B38: 3800 | C38: 8400 | D38: 12500
A39: 800 | B39: 2400 | C39: 4800 | D39: 8000
A40: 600 | B40: 1400 | C40: 4200 | D40: 6500
A41: 1500 | B41: 2600 | C41: 8700 | D41: 11500
A42: 800 | B42: 1800 | C42: 3600 | D42: 7500
A43: 1200 | B43: 4000 | C43: 7800 | D43: 10000
A44: 1300 | B44: 2800 | C44: 6900 | D44: 10500
A45: 1400 | B45: 2800 | C45: 6300 | D45: 13000
A46: 500 | B46: 1200 | C46: 2400 | D46: 4000
A47: 2100 | B47: 5200 | C47: 12600 | D47: 24000
A48: 2600 | B48: 6400 | C48: 13800 | D48: 23000
... A365: 1300 | B365: 3000 | C365: 8700 | D365: 12000

Sheet бигсити йоу сломалось(((
A1: цена_слишком_низкая | B1: цена_выгодная_сделка | C1: цена_завышенная_но_куплю | D1: цена_слишком_высокая | G1: Названия строк | H1: Количество по полю цена_слишком_низкая | J1: Названия строк | K1: Количество по полю цена_выгодная_сделка | M1: Названия строк | N1: Количество по полю цена_завышенная_но_куплю | P1: Названия строк | Q1: Количество по полю цена_слишком_высокая
A2: 1800 | B2: 3800 | C2: 8400 | D2: 14500 | G2: 3000 | H2: 0.0052631579 | J2: 8000 | K2: 0.0052631579 | M2: 7200 | N2: 0.078947368 | P2: 12000 | Q2: 0.073684211
A3: 1400 | B3: 4600 | C3: 7500 | D3: 13500 | G3: 2900 | H3: 0.015789474 | J3: 7600 | K3: 0.021052632 | M3: 7500 | N3: 0.14210526 | P3: 12500 | Q3: 0.22105263
A4: 2000 | B4: 6000 | C4: 14100 | D4: 24500 | G4: 2800 | H4: 0.031578947 | J4: 7400 | K4: 0.047368421 | M4: 7800 | N4: 0.23684211 | P4: 13000 | Q4: 0.35263158
A5: 1300 | B5: 3400 | C5: 9600 | D5: 14000 | G5: 2700 | H5: 0.036842105 | J5: 7200 | K5: 0.052631579 | M5: 8100 | N5: 0.34210526 | P5: 13500 | Q5: 0.47368421
A6: 1100 | B6: 5000 | C6: 7200 | D6: 12500 | G6: 2600 | H6: 0.057894737 | J6: 7000 | K6: 0.068421053 | M6: 8400 | N6: 0.45263158 | P6: 14000 | Q6: 0.61578947
A7: 1800 | B7: 5000 | C7: 8100 | D7: 14000 | G7: 2500 | H7: 0.078947368 | J7: 6800 | K7: 0.094736842 | M7: 8700 | N7: 0.52631579 | P7: 14500 | Q7: 0.73684211
A8: 1500 | B8: 3400 | C8: 9600 | D8: 13000 | G8: 2400 | H8: 0.11052632 | J8: 6600 | K8: 0.11052632 | M8: 9000 | N8: 0.61052632 | P8: 15000 | Q8: 0.8
A9: 1200 | B9: 5000 | C9: 8100 | D9: 13500 | G9: 2300 | H9: 0.13684211 | J9: 6400 | K9: 0.11578947 | M9: 9300 | N9: 0.67894737 | P9: 20000 | Q9: 0.81052632
A10: 1000 | B10: 3200 | C10: 7500 | D10: 13000 | G10: 2200 | H10: 0.15789474 | J10: 6200 | K10: 0.12105263 | M10: 9600 | N10: 0.76842105 | P10: 20500 | Q10: 0.82631579
A11: 2500 | B11: 6600 | C11: 13200 | D11: 22000 | G11: 2100 | H11: 0.17368421 | J11: 6000 | K11: 0.14210526 | M11: 9900 | N11: 0.8 | P11: 21000 | Q11: 0.83684211
A12: 1800 | B12: 4200 | C12: 7800 | D12: 14500 | G12: 2000 | H12: 0.24210526 | J12: 5800 | K12: 0.14736842 | M12: 12300 | N12: 0.81578947 | P12: 21500 | Q12: 0.85789474
A13: 1600 | B13: 4000 | C13: 8700 | D13: 14000 | G13: 1900 | H13: 0.29473684 | J13: 5600 | K13: 0.17368421 | M13: 12600 | N13: 0.83684211 | P13: 22000 | Q13: 0.87368421
... A18: 2000 | B18: 4000 | C18: 9000 | D18: 12500 | G18: 1400 | H18: 0.67894737 | J18: 4600 | K18: 0.40526316 | M18: 14100 | N18: 0.94210526 | P18: 24500 | Q18: 1
A19: 1800 | B19: 4200 | C19: 9900 | D19: 14000 | G19: 1300 | H19: 0.73157895 | J19: 4400 | K19: 0.46842105 | M19: 14400 | N19: 0.94736842
A20: 1200 | B20: 4200 | C20: 9600 | D20: 14500 | G20: 1200 | H20: 0.85263158 | J20: 4200 | K20: 0.54210526 | M20: 14700 | N20: 0.96315789
A21: 1700 | B21: 3000 | C21: 8100 | D21: 12500 | G21: 1100 | H21: 0.94736842 | J21: 4000 | K21: 0.63157895 | M21: 15000 | N21: 0.97894737
A22: 1700 | B22: 3000 | C22: 7200 | D22: 13000 | G22: 1000 | H22: 1 | J22: 3800 | K22: 0.71052632 | M22: 15300 | N22: 0.98421053
A23: 1000 | B23: 5000 | C23: 9600 | D23: 14500 | J23: 3600 | K23: 0.8 | M23: 15900 | N23: 1
A24: 1900 | B24: 4400 | C24: 8700 | D24: 12000 | J24: 3400 | K24: 0.89473684
A25: 1200 | B25: 5000 | C25: 9600 | D25: 13000 | J25: 3200 | K25: 0.95789474
A26: 1100 | B26: 3600 | C26: 9300 | D26: 13000 | J26: 3000 | K26: 1
A27: 1900 | B27: 4000 | C27: 7800 | D27: 13500
A28: 1200 | B28: 4400 | C28: 7200 | D28: 14500
A29: 2100 | B29: 5200 | C29: 12600 | D29: 24000
A30: 2600 | B30: 6400 | C30: 13800 | D30: 23000
A31: 1200 | B31: 3200 | C31: 7800 | D31: 14500
A32: 1600 | B32: 4600 | C32: 9900 | D32: 14000
A33: 2200 | B33: 7200 | C33: 15000 | D33: 21500
A34: 1200 | B34: 3400 | C34: 8700 | D34: 14500
A35: 1400 | B35: 3800 | C35: 9000 | D35: 14500
A36: 1200 | B36: 4800 | C36: 9000 | D36: 12500
A37: 1700 | B37: 4800 | C37: 8400 | D37: 13000
A38: 1900 | B38: 4400 | C38: 9300 | D38: 13500
... A191: 1100 | B191: 4800 | C191: 8400 | D191: 13000

Sheet город миллионник
A1: цена_слишком_низкая | B1: цена_выгодная_сделка | C1: цена_завышенная_но_куплю | D1: цена_слишком_высокая | F1: Названия строк | G1: Количество по полю цена_слишком_низкая | I1: Названия строк | J1: Количество по полю цена_выгодная_сделка | L1: Названия строк | M1: Количество по полю цена_завышенная_но_куплю | O1: Названия строк | P1: Количество по полю цена_слишком_высокая
A2: 1500 | B2: 3800 | C2: 8700 | D2: 16500 | F2: 2500 | G2: 0.0054545455 | I2: 6000 | J2: 0.0054545455 | L2: 3000 | M2: 0.014545455 | O2: 5000 | P2: 0.010909091
A3: 2000 | B3: 4000 | C3: 9900 | D3: 20000 | F3: 2400 | G3: 0.030909091 | I3: 5800 | J3: 0.023636364 | L3: 3300 | M3: 0.04 | O3: 5500 | P3: 0.029090909
A4: 2000 | B4: 3600 | C4: 8400 | D4: 13000 | F4: 2300 | G4: 0.058181818 | I4: 5600 | J4: 0.049090909 | L4: 3600 | M4: 0.063636364 | O4: 6000 | P4: 0.070909091
A5: 1900 | B5: 4400 | C5: 9600 | D5: 18000 | F5: 2200 | G5: 0.069090909 | I5: 5400 | J5: 0.094545455 | L5: 3900 | M5: 0.092727273 | O5: 6500 | P5: 0.090909091
A6: 800 | B6: 2200 | C6: 4800 | D6: 7500 | F6: 2100 | G6: 0.087272727 | I6: 5200 | J6: 0.13636364 | L6: 4200 | M6: 0.13818182 | O6: 7000 | P6: 0.13818182
A7: 1300 | B7: 5000 | C7: 9900 | D7: 14500 | F7: 2000 | G7: 0.11272727 | I7: 5000 | J7: 0.18727273 | L7: 4500 | M7: 0.17818182 | O7: 7500 | P7: 0.18727273
A8: 900 | B8: 1800 | C8: 4800 | D8: 8000 | F8: 1900 | G8: 0.15818182 | I8: 4800 | J8: 0.23272727 | L8: 4800 | M8: 0.21454545 | O8: 8000 | P8: 0.22545455
A9: 1400 | B9: 3800 | C9: 6900 | D9: 11500 | F9: 1800 | G9: 0.20727273 | I9: 4600 | J9: 0.27454545 | L9: 5100 | M9: 0.25090909 | O9: 8500 | P9: 0.25454545
A10: 700 | B10: 2400 | C10: 4800 | D10: 9500 | F10: 1700 | G10: 0.25818182 | I10: 4400 | J10: 0.32909091 | L10: 5400 | M10: 0.28 | O10: 9000 | P10: 0.28
A11: 700 | B11: 2200 | C11: 4800 | D11: 8000 | F11: 1600 | G11: 0.30909091 | I11: 4200 | J11: 0.38727273 | L11: 5700 | M11: 0.30727273 | O11: 9500 | P11: 0.31454545
A12: 1400 | B12: 3800 | C12: 6900 | D12: 13000 | F12: 1500 | G12: 0.36909091 | I12: 4000 | J12: 0.44 | L12: 6000 | M12: 0.33090909 | O12: 10000 | P12: 0.33818182
A13: 1500 | B13: 5600 | C13: 10500 | D13: 16000 | F13: 1400 | G13: 0.43272727 | I13: 3800 | J13: 0.50545455 | L13: 6300 | M13: 0.35090909 | O13: 10500 | P13: 0.36363636
... A24: 1300 | B24: 4400 | C24: 10800 | D24: 15000 | F24: 300 | G24: 1 | I24: 1600 | J24: 0.95636364 | L24: 9600 | M24: 0.71818182 | O24: 16000 | P24: 0.75636364
A25: 700 | B25: 2400 | C25: 5100 | D25: 8500 | I25: 1400 | J25: 0.97454545 | L25: 9900 | M25: 0.78 | O25: 16500 | P25: 0.79818182
A26: 400 | B26: 2000 | C26: 3000 | D26: 5500 | I26: 1200 | J26: 0.99272727 | L26: 10200 | M26: 0.82 | O26: 17000 | P26: 0.83454545
A27: 800 | B27: 2200 | C27: 6000 | D27: 8500 | I27: 1000 | J27: 1 | L27: 10500 | M27: 0.87454545 | O27: 17500 | P27: 0.88727273
A28: 2000 | B28: 5200 | C28: 11700 | D28: 17500 | L28: 10800 | M28: 0.92 | O28: 18000 | P28: 0.93272727
A29: 1900 | B29: 5200 | C29: 8400 | D29: 14000 | L29: 11100 | M29: 0.94727273 | O29: 18500 | P29: 0.94727273
A30: 1500 | B30: 3600 | C30: 10500 | D30: 13500 | L30: 11400 | M30: 0.98 | O30: 19000 | P30: 0.96363636
A31: 1000 | B31: 4800 | C31: 8700 | D31: 15000 | L31: 11700 | M31: 0.99454545 | O31: 19500 | P31: 0.98727273
A32: 900 | B32: 2000 | C32: 4200 | D32: 8000 | L32: 12000 | M32: 1 | O32: 20000 | P32: 1
A33: 800 | B33: 2400 | C33: 6000 | D33: 7500
A34: 1800 | B34: 4600 | C34: 10200 | D34: 14500
A35: 1000 | B35: 1600 | C35: 4200 | D35: 8000
A36: 1400 | B36: 4200 | C36: 9900 | D36: 17000
A37: 1500 | B37: 4400 | C37: 11100 | D37: 15500
A38: 1600 | B38: 4000 | C38: 9300 | D38: 17000
A39: 2300 | B39: 4200 | C39: 9900 | D39: 16500
A40: 2100 | B40: 5200 | C40: 9600 | D40: 18500
A41: 2300 | B41: 5600 | C41: 11100 | D41: 19500
A42: 1300 | B42: 5000 | C42: 9300 | D42: 17500
A43: 800 | B43: 2400 | C43: 4800 | D43: 8500
A44: 600 | B44: 2400 | C44: 4800 | D44: 9000
... A551: 1300 | B551: 3000 | C551: 8700 | D551: 12000

Sheet бездетные
A1: цена_слишком_низкая | B1: цена_выгодная_сделка | C1: цена_завышенная_но_куплю | D1: цена_слишком_высокая | F1: Названия строк | G1: Количество по полю цена_слишком_низкая | I1: Названия строк | J1: Количество по полю цена_выгодная_сделка | L1: Названия строк | M1: Количество по полю цена_завышенная_но_куплю | O1: Названия строк | P1: Количество по полю цена_слишком_высокая
A2: 1500 | B2: 3800 | C2: 8700 | D2: 16500 | F2: 3000 | G2: 0.0020283976 | I2: 8000 | J2: 0.0020283976 | L2: 3000 | M2: 0.016227181 | O2: 5000 | P2: 0.012170385
A3: 1800 | B3: 3800 | C3: 8400 | D3: 14500 | F3: 2900 | G3: 0.0060851927 | I3: 7600 | J3: 0.0081135903 | L3: 3300 | M3: 0.044624746 | O3: 5500 | P3: 0.032454361
A4: 2000 | B4: 3600 | C4: 8400 | D4: 13000 | F4: 2800 | G4: 0.012170385 | I4: 7400 | J4: 0.018255578 | L4: 3600 | M4: 0.052738337 | O4: 6000 | P4: 0.070993915
A5: 2000 | B5: 6000 | C5: 14100 | D5: 24500 | F5: 2700 | G5: 0.014198783 | I5: 7200 | J5: 0.020283976 | L5: 3900 | M5: 0.068965517 | O5: 6500 | P5: 0.0831643
A6: 1300 | B6: 5000 | C6: 9900 | D6: 14500 | F6: 2600 | G6: 0.022312373 | I6: 7000 | J6: 0.026369168 | L6: 4200 | M6: 0.10953347 | O6: 7000 | P6: 0.11561866
A7: 900 | B7: 1800 | C7: 4800 | D7: 8000 | F7: 2500 | G7: 0.030425963 | I7: 6800 | J7: 0.036511156 | L7: 4500 | M7: 0.14198783 | O7: 7500 | P7: 0.15010142
A8: 1400 | B8: 3800 | C8: 6900 | D8: 11500 | F8: 2400 | G8: 0.042596349 | I8: 6600 | J8: 0.042596349 | L8: 4800 | M8: 0.17444219 | O8: 8000 | P8: 0.18255578
A9: 700 | B9: 2400 | C9: 4800 | D9: 9500 | F9: 2300 | G9: 0.052738337 | I9: 6400 | J9: 0.044624746 | L9: 5100 | M9: 0.21095335 | O9: 8500 | P9: 0.21501014
A10: 1500 | B10: 3400 | C10: 9600 | D10: 13000 | F10: 2200 | G10: 0.060851927 | I10: 6200 | J10: 0.046653144 | L10: 5400 | M10: 0.24340771 | O10: 9000 | P10: 0.24340771
A11: 700 | B11: 2200 | C11: 4800 | D11: 8000 | F11: 2100 | G11: 0.06693712 | I11: 6000 | J11: 0.054766734 | L11: 5700 | M11: 0.27383367 | O11: 9500 | P11: 0.28194726
A12: 1400 | B12: 3800 | C12: 6900 | D12: 13000 | F12: 2000 | G12: 0.089249493 | I12: 5800 | J12: 0.056795132 | L12: 6000 | M12: 0.30020284 | O12: 10000 | P12: 0.30831643
A13: 1200 | B13: 5000 | C13: 8100 | D13: 13500 | F13: 1900 | G13: 0.13184584 | I13: 5600 | J13: 0.06693712 | L13: 6300 | M13: 0.32251521 | O13: 10500 | P13: 0.336714
... A29: 1600 | B29: 4400 | C29: 8100 | D29: 14000 | F29: 300 | G29: 1 | I29: 2400 | J29: 0.75659229 | L29: 11100 | M29: 0.92292089 | O29: 20000 | P29: 0.92697769
A30: 900 | B30: 2000 | C30: 4200 | D30: 8000 | I30: 2200 | J30: 0.78093306 | L30: 12300 | M30: 0.92900609 | O30: 20500 | P30: 0.93306288
A31: 800 | B31: 2400 | C31: 6000 | D31: 7500 | I31: 2000 | J31: 0.831643 | L31: 12600 | M31: 0.93711968 | O31: 21000 | P31: 0.93711968
A32: 1800 | B32: 4600 | C32: 10200 | D32: 14500 | I32: 1800 | J32: 0.88640974 | L32: 12900 | M32: 0.94523327 | O32: 21500 | P32: 0.94523327
A33: 1000 | B33: 1600 | C33: 4200 | D33: 8000 | I33: 1600 | J33: 0.95131846 | L33: 13200 | M33: 0.95537525 | O33: 22000 | P33: 0.95131846
A34: 1900 | B34: 4600 | C34: 8400 | D34: 13500 | I34: 1400 | J34: 0.97160243 | L34: 13500 | M34: 0.96551724 | O34: 22500 | P34: 0.95943205
A35: 1400 | B35: 4200 | C35: 9900 | D35: 17000 | I35: 1200 | J35: 0.99188641 | L35: 13800 | M35: 0.96957404 | O35: 23000 | P35: 0.96348884
A36: 2400 | B36: 5400 | C36: 15000 | D36: 21000 | I36: 1000 | J36: 1 | L36: 14100 | M36: 0.97768763 | O36: 23500 | P36: 0.96754564
A37: 1600 | B37: 4000 | C37: 9300 | D37: 17000 | L37: 14400 | M37: 0.97971602 | O37: 24000 | P37: 0.98782961
A38: 1300 | B38: 5000 | C38: 9300 | D38: 17500 | L38: 14700 | M38: 0.98580122 | O38: 24500 | P38: 1
A39: 800 | B39: 2400 | C39: 4800 | D39: 8500 | L39: 15000 | M39: 0.99188641
A40: 600 | B40: 2400 | C40: 4800 | D40: 9000 | L40: 15300 | M40: 0.99391481
A41: 600 | B41: 2000 | C41: 5700 | D41: 9000 | L41: 15900 | M41: 1
A42: 600 | B42: 1000 | C42: 3300 | D42: 6000
A43: 1500 | B43: 5200 | C43: 9000 | D43: 14000
A44: 1000 | B44: 3800 | C44: 7200 | D44: 10000
A45: 1400 | B45: 3400 | C45: 7800 | D45: 10500
A46: 1400 | B46: 3600 | C46: 7200 | D46: 10500
A47: 500 | B47: 1600 | C47: 4200 | D47: 6000
A48: 900 | B48: 2400 | C48: 4500 | D48: 8500
A49: 900 | B49: 3800 | C49: 9000 | D49: 13000
A50: 1100 | B50: 5400 | C50: 10500 | D50: 16000
A51: 1100 | B51: 3800 | C51: 8400 | D51: 12500
A52: 1700 | B52: 3000 | C52: 7200 | D52: 13000
A53: 700 | B53: 2200 | C53: 5100 | D53: 9500
... A494: 1300 | B494: 3000 | C494: 8700 | D494: 12000
