Workbook

Sheet Данные
A1: ФИО менеджера | B1: ФИО клиента | C1: Дата сделки | D1: Сумма сделки | E1: NPS
A2: Громова Мария Ильинична | B2: Волкова Валерия Алексеевна | C2: 2023-09-01 | D2: 49585 | E2: 5
A3: Сидорова Елена Васильевна | B3: Морозов Егор Андреевич | C3: 2023-09-01 | D3: 70374 | E3: 1
A4: Семенова Ирина Валерьевна | B4: Орлов Константин Станиславович | C4: 2023-09-04 | D4: 17347 | E4: 8
A5: Иванова Анна Сергеевна | B5: Иванова Наталья Дмитриевна | C5: 2023-09-04 | D5: 77152 | E5: 10
A6: Громова Мария Ильинична | B6: Николаев Матвей Викторович | C6: 2023-09-04 | D6: 25583 | E6: 7
A7: Фролов Сергей Викторович | B7: Козлова Полина Артемовна | C7: 2023-09-04 | D7: 50424 | E7: 3
A8: Петров Владимир Кириллович | B8: Орлова Анна Романовна | C8: 2023-09-04 | D8: 27772 | E8: 1
A9: Петров Владимир Кириллович | B9: Лебедева Александра Дмитриевна | C9: 2023-09-04 | D9: 58246 | E9: 8
A10: Иванова Анна Сергеевна | B10: Волкова Ольга Андреевна | C10: 2023-09-04 | D10: 30493 | E10: 4
A11: Семенова Ирина Валерьевна | B11: Петров Алексей Юрьевич | C11: 2023-09-05 | D11: 66366 | E11: 4
A12: Петров Владимир Кириллович | B12: Волкова Наталья Андреевна | C12: 2023-09-05 | D12: 25078 | E12: 6
A13: Белов Алексей Константинович | B13: Смирнов Илья Олегович | C13: 2023-09-05 | D13: 75327 | E13: 8
... A1001: Ткаченко Андрей Олегович | B1001: Попова Людмила Егоровна | C1001: 2024-09-02 | D1001: 80783 | E1001: 6

Sheet результат
A1: ФИО студента: | B1: Репин Антон Сергеевич
A2: Задача 1 | B2: Для каждого менеджера найти метрики: | G2: ФИО Менеджера (по алфавиту) | H2: Клиенты | I2: Сумма | J2: Длительность, дни | K2: NPS
B3: - количество клиентов - (столбец H) | F3: 1 | G3: Белов Алексей Константинович | H3: 64 | I3: 4182260 | J3: 312 | K3: =(COUNTIFS(Данные!A:A,результат!G3,Данные!E:E,">=9") - COUNTIFS(Данные!A:A,результат!G3,Данные!E:E,">=6") ) / COUNTIFS(Данные!A:A,результат!G3,Данные!E:E,">=0") -> -0.45454545
B4: - сумма проектов - (столбец I) | F4: 2 | G4: Громова Мария Ильинична | H4: 67 | I4: 3947444 | J4: 345 | K4: =(COUNTIFS(Данные!A:A,результат!G4,Данные!E:E,">=9") - COUNTIFS(Данные!A:A,результат!G4,Данные!E:E,">=6") ) / COUNTIFS(Данные!A:A,результат!G4,Данные!E:E,">=0") -> -0.5
B5: - длительность работы с клиентом от первой сделки до последней - (столбец J) | F5: 3 | G5: Иванова Анна Сергеевна | H5: 68 | I5: 4423866 | J5: 294 | K5: =(COUNTIFS(Данные!A:A,результат!G5,Данные!E:E,">=9") - COUNTIFS(Данные!A:A,результат!G5,Данные!E:E,">=6") ) / COUNTIFS(Данные!A:A,результат!G5,Данные!E:E,">=0") -> -0.39240506
B6: (для каждого менеджера определить самого долгого клиента в днях | F6: 4 | G6: Кузнецов Дмитрий Львович | H6: 62 | I6: 3756093 | J6: 303 | K6: =(COUNTIFS(Данные!A:A,результат!G6,Данные!E:E,">=9") - COUNTIFS(Данные!A:A,результат!G6,Данные!E:E,">=6") ) / COUNTIFS(Данные!A:A,результат!G6,Данные!E:E,">=0") -> -0.53424658
B7: от даты заключения первого проекта до даты заключения последнего проекта). | F7: 5 | G7: Новикова Ольга Петровна | H7: 73 | I7: 4681158 | J7: 280 | K7: =(COUNTIFS(Данные!A:A,результат!G7,Данные!E:E,">=9") - COUNTIFS(Данные!A:A,результат!G7,Данные!E:E,">=6") ) / COUNTIFS(Данные!A:A,результат!G7,Данные!E:E,">=0") -> -0.41304348
B8: - NPS по всем проектам - (столбец K) | F8: 6 | G8: Орлов Павел Денисович | H8: 66 | I8: 4632492 | J8: 225 | K8: =(COUNTIFS(Данные!A:A,результат!G8,Данные!E:E,">=9") - COUNTIFS(Данные!A:A,результат!G8,Данные!E:E,">=6") ) / COUNTIFS(Данные!A:A,результат!G8,Данные!E:E,">=0") -> -0.47058824
F9: 7 | G9: Петров Владимир Кириллович | H9: 61 | I9: 3621754 | J9: 323 | K9: =(COUNTIFS(Данные!A:A,результат!G9,Данные!E:E,">=9") - COUNTIFS(Данные!A:A,результат!G9,Данные!E:E,">=6") ) / COUNTIFS(Данные!A:A,результат!G9,Данные!E:E,">=0") -> -0.60810811
F10: 8 | G10: Семенова Ирина Валерьевна | H10: 68 | I10: 5034957 | J10: 360 | K10: =(COUNTIFS(Данные!A:A,результат!G10,Данные!E:E,">=9") - COUNTIFS(Данные!A:A,результат!G10,Данные!E:E,">=6") ) / COUNTIFS(Данные!A:A,результат!G10,Данные!E:E,">=0") -> -0.45882353
F11: 9 | G11: Сидорова Елена Васильевна | H11: 72 | I11: 4946753 | J11: 293 | K11: =(COUNTIFS(Данные!A:A,результат!G11,Данные!E:E,">=9") - COUNTIFS(Данные!A:A,результат!G11,Данные!E:E,">=6") ) / COUNTIFS(Данные!A:A,результат!G11,Данные!E:E,">=0") -> -0.52173913
B12: Определить самого эффективного менеджера: | F12: 10 | G12: Ткаченко Андрей Олегович | H12: 64 | I12: 4235998 | J12: 295 | K12: =(COUNTIFS(Данные!A:A,результат!G12,Данные!E:E,">=9") - COUNTIFS(Данные!A:A,результат!G12,Данные!E:E,">=6") ) / COUNTIFS(Данные!A:A,результат!G12,Данные!E:E,">=0") -> -0.44155844
A13: по количеству клиентов | B13: =INDEX(G3:G14,MATCH(MAX(H3:H14),H3:H14,0)) -> Яковлев Артем Игоревич | F13: 11 | G13: Фролов Сергей Викторович | H13: 59 | I13: 4415812 | J13: 347 | K13: =(COUNTIFS(Данные!A:A,результат!G13,Данные!E:E,">=9") - COUNTIFS(Данные!A:A,результат!G13,Данные!E:E,">=6") ) / COUNTIFS(Данные!A:A,результат!G13,Данные!E:E,">=0") -> -0.51219512
F14: 12 | G14: Яковлев Артем Игоревич | H14: 82 | I14: 5887985 | J14: 296 | K14: =(COUNTIFS(Данные!A:A,результат!G14,Данные!E:E,">=9") - COUNTIFS(Данные!A:A,результат!G14,Данные!E:E,">=6") ) / COUNTIFS(Данные!A:A,результат!G14,Данные!E:E,">=0") -> -0.51886792
A15: по сумме проектов | B15: =INDEX(G3:G14,MATCH(MAX(I3:I14),I3:I14,0)) -> Яковлев Артем Игоревич
A17: по длительности работы | B17: =INDEX(G3:G14,MATCH(MAX(J3:J14),J3:J14,0)) -> Семенова Ирина Валерьевна
A19: NPS | B19: =INDEX(G3:G14,MATCH(MAX(K3:K14),K3:K14,0)) -> Иванова Анна Сергеевна
A23: Задача 2 | B23: Оценить клиентов | G23: ТОП 10 клиентов по продажам
B24: - доходности (вывести топ 10 клиентов) | G24: ФИО | H24: Проекты | I24: Сумма
B25: - не переходил к другим менеджерам - вывести первых 10 по алфавиту | F25: 1 | G25: Новиков Матвей Егорович | H25: 14 | I25: 759518
B26: - по длительности (сколько месяцев суммарно обслуживался клиент) | F26: 2 | G26: Степанова София Михайловна | H26: 12 | I26: 731183
F27: 3 | G27: Попов Никита Геннадьевич | H27: 11 | I27: 616804
F28: 4 | G28: Степанов Дмитрий Иванович | H28: 11 | I28: 589442
F29: 5 | G29: Павлов Сергей Артемович | H29: 11 | I29: 575295
F30: 6 | G30: Сидоров Владимир Артемович | H30: 9 | I30: 574422
F31: 7 | G31: Морозов Максим Сергеевич | H31: 9 | I31: 561893
F32: 8 | G32: Орлова Анна Артемовна | H32: 8 | I32: 554461
F33: 9 | G33: Петрова Алиса Станиславовна | H33: 8 | I33: 553432
F34: 10 | G34: Петров Роман Алексеевич | H34: 9 | I34: 539765
G37: 10 клиентов, которые обслуживались у одного менеджера (в алфавитном порядке)
G38: ФИО | H38: Проекты | I38: Сумма
F39: 1 | G39: Егорова Алиса Михайловна | H39: 3 | I39: 272074
F40: 2 | G40: Иванова Наталья Михайловна | H40: 2 | I40: 171684
F41: 3 | G41: Николаев Иван Сергеевич | H41: 2 | I41: 149369
F42: 4 | G42: Новиков Артем Павлович | H42: 1 | I42: 99945
F43: 5 | G43: Сидорова Людмила Никитична | H43: 1 | I43: 55635
F44: 6 | G44: Лебедева Алиса Ивановна | H44: 1 | I44: 52464
F45: 7 | G45: Волкова Ольга Геннадьевна | H45: 1 | I45: 42249
F46: 8 | G46: Петрова Александра Романовна | H46: 1 | I46: 41145
F47: 9 | G47: Орлов Дмитрий Павлович | H47: 1 | I47: 40657
...

Sheet Задача 1
D1: ФИО менеджера | E1: ФИО клиента | F1: Дата первой сделки | G1: Дата последней сделки | L1: ФИО менеджера | M1: ФИО клиента | N1: Дата сделки | S1: Мен_Кл | T1: ФИО менеджера | U1: ФИО клиента | V1: Дата сделки
A2: Белов Алексей Константинович | D2: Громова Мария Ильинична | E2: Волкова Валерия Алексеевна | F2: =VLOOKUP(D2&E2,S:V,4,0) -> 2023-09-01 | G2: =VLOOKUP(D2&E2,K:N,4,0) -> 2023-09-01 | H2: =G2-F2 -> 0 | K2: =L2&M2 -> Новикова Ольга ПетровнаНиколаева Наталья Геннадьевна | L2: Новикова Ольга Петровна | M2: Николаева Наталья Геннадьевна | N2: 2024-09-02 | S2: =T2&U2 -> Громова Мария ИльиничнаВолкова Валерия Алексеевна | T2: Громова Мария Ильинична | U2: Волкова Валерия Алексеевна | V2: 2023-09-01
A3: Громова Мария Ильинична | D3: Сидорова Елена Васильевна | E3: Морозов Егор Андреевич | F3: =VLOOKUP(D3&E3,S:V,4,0) -> 2023-09-01 | G3: =VLOOKUP(D3&E3,K:N,4,0) -> 2024-06-20 | H3: =G3-F3 -> 293 | K3: =L3&M3 -> Ткаченко Андрей ОлеговичПопова Людмила Егоровна | L3: Ткаченко Андрей Олегович | M3: Попова Людмила Егоровна | N3: 2024-09-02 | S3: =T3&U3 -> Сидорова Елена ВасильевнаМорозов Егор Андреевич | T3: Сидорова Елена Васильевна | U3: Морозов Егор Андреевич | V3: 2023-09-01
A4: Иванова Анна Сергеевна | D4: Семенова Ирина Валерьевна | E4: Орлов Константин Станиславович | F4: =VLOOKUP(D4&E4,S:V,4,0) -> 2023-09-04 | G4: =VLOOKUP(D4&E4,K:N,4,0) -> 2024-08-29 | H4: =G4-F4 -> 360 | K4: =L4&M4 -> Фролов Сергей ВикторовичСтепанов Дмитрий Иванович | L4: Фролов Сергей Викторович | M4: Степанов Дмитрий Иванович | N4: 2024-08-30 | S4: =T4&U4 -> Семенова Ирина ВалерьевнаОрлов Константин Станиславович | T4: Семенова Ирина Валерьевна | U4: Орлов Константин Станиславович | V4: 2023-09-04
A5: Кузнецов Дмитрий Львович | D5: Иванова Анна Сергеевна | E5: Иванова Наталья Дмитриевна | F5: =VLOOKUP(D5&E5,S:V,4,0) -> 2023-09-04 | G5: =VLOOKUP(D5&E5,K:N,4,0) -> 2023-09-04 | H5: =G5-F5 -> 0 | K5: =L5&M5 -> Кузнецов Дмитрий ЛьвовичПетрова Александра Олеговна | L5: Кузнецов Дмитрий Львович | M5: Петрова Александра Олеговна | N5: 2024-08-30 | S5: =T5&U5 -> Иванова Анна СергеевнаИванова Наталья Дмитриевна | T5: Иванова Анна Сергеевна | U5: Иванова Наталья Дмитриевна | V5: 2023-09-04
A6: Новикова Ольга Петровна | D6: Громова Мария Ильинична | E6: Николаев Матвей Викторович | F6: =VLOOKUP(D6&E6,S:V,4,0) -> 2023-09-04 | G6: =VLOOKUP(D6&E6,K:N,4,0) -> 2024-08-14 | H6: =G6-F6 -> 345 | K6: =L6&M6 -> Семенова Ирина ВалерьевнаОрлов Константин Станиславович | L6: Семенова Ирина Валерьевна | M6: Орлов Константин Станиславович | N6: 2024-08-29 | S6: =T6&U6 -> Громова Мария ИльиничнаНиколаев Матвей Викторович | T6: Громова Мария Ильинична | U6: Николаев Матвей Викторович | V6: 2023-09-04
A7: Орлов Павел Денисович | D7: Фролов Сергей Викторович | E7: Козлова Полина Артемовна | F7: =VLOOKUP(D7&E7,S:V,4,0) -> 2023-09-04 | G7: =VLOOKUP(D7&E7,K:N,4,0) -> 2023-11-15 | H7: =G7-F7 -> 72 | K7: =L7&M7 -> Ткаченко Андрей ОлеговичПетрова Александра Ильинична | L7: Ткаченко Андрей Олегович | M7: Петрова Александра Ильинична | N7: 2024-08-29 | S7: =T7&U7 -> Фролов Сергей ВикторовичКозлова Полина Артемовна | T7: Фролов Сергей Викторович | U7: Козлова Полина Артемовна | V7: 2023-09-04
A8: Петров Владимир Кириллович | D8: Петров Владимир Кириллович | E8: Орлова Анна Романовна | F8: =VLOOKUP(D8&E8,S:V,4,0) -> 2023-09-04 | G8: =VLOOKUP(D8&E8,K:N,4,0) -> 2024-05-02 | H8: =G8-F8 -> 241 | K8: =L8&M8 -> Ткаченко Андрей ОлеговичЛебедева Ольга Романовна | L8: Ткаченко Андрей Олегович | M8: Лебедева Ольга Романовна | N8: 2024-08-29 | S8: =T8&U8 -> Петров Владимир КирилловичОрлова Анна Романовна | T8: Петров Владимир Кириллович | U8: Орлова Анна Романовна | V8: 2023-09-04
A9: Семенова Ирина Валерьевна | D9: Петров Владимир Кириллович | E9: Лебедева Александра Дмитриевна | F9: =VLOOKUP(D9&E9,S:V,4,0) -> 2023-09-04 | G9: =VLOOKUP(D9&E9,K:N,4,0) -> 2023-09-04 | H9: =G9-F9 -> 0 | K9: =L9&M9 -> Фролов Сергей ВикторовичСтепанов Дмитрий Иванович | L9: Фролов Сергей Викторович | M9: Степанов Дмитрий Иванович | N9: 2024-08-29 | S9: =T9&U9 -> Петров Владимир КирилловичЛебедева Александра Дмитриевна | T9: Петров Владимир Кириллович | U9: Лебедева Александра Дмитриевна | V9: 2023-09-04
A10: Сидорова Елена Васильевна | D10: Иванова Анна Сергеевна | E10: Волкова Ольга Андреевна | F10: =VLOOKUP(D10&E10,S:V,4,0) -> 2023-09-04 | G10: =VLOOKUP(D10&E10,K:N,4,0) -> 2023-09-04 | H10: =G10-F10 -> 0 | K10: =L10&M10 -> Фролов Сергей ВикторовичКузнецова Валерия Дмитриевна | L10: Фролов Сергей Викторович | M10: Кузнецова Валерия Дмитриевна | N10: 2024-08-28 | S10: =T10&U10 -> Иванова Анна СергеевнаВолкова Ольга Андреевна | T10: Иванова Анна Сергеевна | U10: Волкова Ольга Андреевна | V10: 2023-09-04
A11: Ткаченко Андрей Олегович | D11: Семенова Ирина Валерьевна | E11: Петров Алексей Юрьевич | F11: =VLOOKUP(D11&E11,S:V,4,0) -> 2023-09-05 | G11: =VLOOKUP(D11&E11,K:N,4,0) -> 2024-05-31 | H11: =G11-F11 -> 269 | K11: =L11&M11 -> Новикова Ольга ПетровнаНиколаева Наталья Геннадьевна | L11: Новикова Ольга Петровна | M11: Николаева Наталья Геннадьевна | N11: 2024-08-28 | S11: =T11&U11 -> Семенова Ирина ВалерьевнаПетров Алексей Юрьевич | T11: Семенова Ирина Валерьевна | U11: Петров Алексей Юрьевич | V11: 2023-09-05
A12: Фролов Сергей Викторович | D12: Петров Владимир Кириллович | E12: Волкова Наталья Андреевна | F12: =VLOOKUP(D12&E12,S:V,4,0) -> 2023-09-05 | G12: =VLOOKUP(D12&E12,K:N,4,0) -> 2023-09-05 | H12: =G12-F12 -> 0 | K12: =L12&M12 -> Сидорова Елена ВасильевнаФедорова Ксения Павловна | L12: Сидорова Елена Васильевна | M12: Федорова Ксения Павловна | N12: 2024-08-27 | S12: =T12&U12 -> Петров Владимир КирилловичВолкова Наталья Андреевна | T12: Петров Владимир Кириллович | U12: Волкова Наталья Андреевна | V12: 2023-09-05
A13: Яковлев Артем Игоревич | D13: Белов Алексей Константинович | E13: Смирнов Илья Олегович | F13: =VLOOKUP(D13&E13,S:V,4,0) -> 2023-09-05 | G13: =VLOOKUP(D13&E13,K:N,4,0) -> 2023-09-05 | H13: =G13-F13 -> 0 | K13: =L13&M13 -> Иванова Анна СергеевнаОрлова Анна Артемовна | L13: Иванова Анна Сергеевна | M13: Орлова Анна Артемовна | N13: 2024-08-27 | S13: =T13&U13 -> Белов Алексей КонстантиновичСмирнов Илья Олегович | T13: Белов Алексей Константинович | U13: Смирнов Илья Олегович | V13: 2023-09-05
D14: Ткаченко Андрей Олегович | E14: Козлова Татьяна Сергеевна | F14: =VLOOKUP(D14&E14,S:V,4,0) -> 2023-09-06 | G14: =VLOOKUP(D14&E14,K:N,4,0) -> 2023-11-23 | H14: =G14-F14 -> 78 | K14: =L14&M14 -> Новикова Ольга ПетровнаНиколаева София Никитична | L14: Новикова Ольга Петровна | M14: Николаева София Никитична | N14: 2024-08-27 | S14: =T14&U14 -> Ткаченко Андрей ОлеговичКозлова Татьяна Сергеевна | T14: Ткаченко Андрей Олегович | U14: Козлова Татьяна Сергеевна | V14: 2023-09-06
D15: Яковлев Артем Игоревич | E15: Васильев Артур Артемович | F15: =VLOOKUP(D15&E15,S:V,4,0) -> 2023-09-06 | G15: =VLOOKUP(D15&E15,K:N,4,0) -> 2023-12-08 | H15: =G15-F15 -> 93 | K15: =L15&M15 -> Орлов Павел ДенисовичПетрова Александра Ильинична | L15: Орлов Павел Денисович | M15: Петрова Александра Ильинична | N15: 2024-08-26 | S15: =T15&U15 -> Яковлев Артем ИгоревичВасильев Артур Артемович | T15: Яковлев Артем Игоревич | U15: Васильев Артур Артемович | V15: 2023-09-06
D16: Иванова Анна Сергеевна | E16: Сидоров Владимир Артемович | F16: =VLOOKUP(D16&E16,S:V,4,0) -> 2023-09-06 | G16: =VLOOKUP(D16&E16,K:N,4,0) -> 2023-09-06 | H16: =G16-F16 -> 0 | K16: =L16&M16 -> Белов Алексей КонстантиновичВолков Алексей Егорович | L16: Белов Алексей Константинович | M16: Волков Алексей Егорович | N16: 2024-08-26 | S16: =T16&U16 -> Иванова Анна СергеевнаСидоров Владимир Артемович | T16: Иванова Анна Сергеевна | U16: Сидоров Владимир Артемович | V16: 2023-09-06
D17: Белов Алексей Константинович | E17: Новиков Матвей Егорович | F17: =VLOOKUP(D17&E17,S:V,4,0) -> 2023-09-07 | G17: =VLOOKUP(D17&E17,K:N,4,0) -> 2023-09-07 | H17: =G17-F17 -> 0 | K17: =L17&M17 -> Фролов Сергей ВикторовичНовиков Матвей Егорович | L17: Фролов Сергей Викторович | M17: Новиков Матвей Егорович | N17: 2024-08-26 | S17: =T17&U17 -> Белов Алексей КонстантиновичНовиков Матвей Егорович | T17: Белов Алексей Константинович | U17: Новиков Матвей Егорович | V17: 2023-09-07
D18: Фролов Сергей Викторович | E18: Лебедева Александра Дмитриевна | F18: =VLOOKUP(D18&E18,S:V,4,0) -> 2023-09-07 | G18: =VLOOKUP(D18&E18,K:N,4,0) -> 2023-09-07 | H18: =G18-F18 -> 0 | K18: =L18&M18 -> Яковлев Артем ИгоревичСеменов Роман Павлович | L18: Яковлев Артем Игоревич | M18: Семенов Роман Павлович | N18: 2024-08-26 | S18: =T18&U18 -> Фролов Сергей ВикторовичЛебедева Александра Дмитриевна | T18: Фролов Сергей Викторович | U18: Лебедева Александра Дмитриевна | V18: 2023-09-07
D19: Фролов Сергей Викторович | E19: Семенов Алексей Владимирович | F19: =VLOOKUP(D19&E19,S:V,4,0) -> 2023-09-07 | G19: =VLOOKUP(D19&E19,K:N,4,0) -> 2023-09-07 | H19: =G19-F19 -> 0 | K19: =L19&M19 -> Фролов Сергей ВикторовичПопов Михаил Павлович | L19: Фролов Сергей Викторович | M19: Попов Михаил Павлович | N19: 2024-08-26 | S19: =T19&U19 -> Фролов Сергей ВикторовичСеменов Алексей Владимирович | T19: Фролов Сергей Викторович | U19: Семенов Алексей Владимирович | V19: 2023-09-07
D20: Сидорова Елена Васильевна | E20: Павлов Никита Иванович | F20: =VLOOKUP(D20&E20,S:V,4,0) -> 2023-09-07 | G20: =VLOOKUP(D20&E20,K:N,4,0) -> 2023-09-07 | H20: =G20-F20 -> 0 | K20: =L20&M20 -> Белов Алексей КонстантиновичФедоров Владимир Павлович | L20: Белов Алексей Константинович | M20: Федоров Владимир Павлович | N20: 2024-08-26 | S20: =T20&U20 -> Сидорова Елена ВасильевнаПавлов Никита Иванович | T20: Сидорова Елена Васильевна | U20: Павлов Никита Иванович | V20: 2023-09-07
D21: Сидорова Елена Васильевна | E21: Смирнов Константин Кириллович | F21: =VLOOKUP(D21&E21,S:V,4,0) -> 2023-09-07 | G21: =VLOOKUP(D21&E21,K:N,4,0) -> 2023-09-07 | H21: =G21-F21 -> 0 | K21: =L21&M21 -> Сидорова Елена ВасильевнаНовиков Матвей Егорович | L21: Сидорова Елена Васильевна | M21: Новиков Матвей Егорович | N21: 2024-08-26 | S21: =T21&U21 -> Сидорова Елена ВасильевнаСмирнов Константин Кириллович | T21: Сидорова Елена Васильевна | U21: Смирнов Константин Кириллович | V21: 2023-09-07
D22: Кузнецов Дмитрий Львович | E22: Смирнова Татьяна Александровна | F22: =VLOOKUP(D22&E22,S:V,4,0) -> 2023-09-08 | G22: =VLOOKUP(D22&E22,K:N,4,0) -> 2023-09-08 | H22: =G22-F22 -> 0 | K22: =L22&M22 -> Белов Алексей КонстантиновичОрлов Константин Станиславович | L22: Белов Алексей Константинович | M22: Орлов Константин Станиславович | N22: 2024-08-26 | S22: =T22&U22 -> Кузнецов Дмитрий ЛьвовичСмирнова Татьяна Александровна | T22: Кузнецов Дмитрий Львович | U22: Смирнова Татьяна Александровна | V22: 2023-09-08
D23: Фролов Сергей Викторович | E23: Семенова Светлана Дмитриевна | F23: =VLOOKUP(D23&E23,S:V,4,0) -> 2023-09-08 | G23: =VLOOKUP(D23&E23,K:N,4,0) -> 2024-08-16 | H23: =G23-F23 -> 343 | K23: =L23&M23 -> Новикова Ольга ПетровнаСмирнов Александр Иванович | L23: Новикова Ольга Петровна | M23: Смирнов Александр Иванович | N23: 2024-08-26 | S23: =T23&U23 -> Фролов Сергей ВикторовичСеменова Светлана Дмитриевна | T23: Фролов Сергей Викторович | U23: Семенова Светлана Дмитриевна | V23: 2023-09-08
D24: Петров Владимир Кириллович | E24: Кузнецова Мария Дмитриевна | F24: =VLOOKUP(D24&E24,S:V,4,0) -> 2023-09-08 | G24: =VLOOKUP(D24&E24,K:N,4,0) -> 2023-09-08 | H24: =G24-F24 -> 0 | K24: =L24&M24 -> Ткаченко Андрей ОлеговичПопов Михаил Павлович | L24: Ткаченко Андрей Олегович | M24: Попов Михаил Павлович | N24: 2024-08-26 | S24: =T24&U24 -> Петров Владимир КирилловичКузнецова Мария Дмитриевна | T24: Петров Владимир Кириллович | U24: Кузнецова Мария Дмитриевна | V24: 2023-09-08
D25: Петров Владимир Кириллович | E25: Федорова Наталья Геннадьевна | F25: =VLOOKUP(D25&E25,S:V,4,0) -> 2023-09-11 | G25: =VLOOKUP(D25&E25,K:N,4,0) -> 2023-09-11 | H25: =G25-F25 -> 0 | K25: =L25&M25 -> Петров Владимир КирилловичМорозов Егор Андреевич | L25: Петров Владимир Кириллович | M25: Морозов Егор Андреевич | N25: 2024-08-23 | S25: =T25&U25 -> Петров Владимир КирилловичФедорова Наталья Геннадьевна | T25: Петров Владимир Кириллович | U25: Федорова Наталья Геннадьевна | V25: 2023-09-11
... D807: Ткаченко Андрей Олегович | E807: Попова Людмила Егоровна | F807: =VLOOKUP(D807&E807,S:V,4,0) -> 2024-09-02 | G807: =VLOOKUP(D807&E807,K:N,4,0) -> 2024-09-02 | H807: =G807-F807 -> 0 | K807: =L807&M807 -> Яковлев Артем ИгоревичИванова Анна Егоровна | L807: Яковлев Артем Игоревич | M807: Иванова Анна Егоровна | N807: 2023-11-13 | S807: =T807&U807 -> Семенова Ирина ВалерьевнаФедорова Алиса Викторовна | T807: Семенова Ирина Валерьевна | U807: Федорова Алиса Викторовна | V807: 2024-06-26
K808: =L808&M808 -> Яковлев Артем ИгоревичСтепанов Сергей Егорович | L808: Яковлев Артем Игоревич | M808: Степанов Сергей Егорович | N808: 2023-11-10 | S808: =T808&U808 -> Орлов Павел ДенисовичСтепанова Ольга Андреевна | T808: Орлов Павел Денисович | U808: Степанова Ольга Андреевна | V808: 2024-06-27
K809: =L809&M809 -> Фролов Сергей ВикторовичПетров Роман Алексеевич | L809: Фролов Сергей Викторович | M809: Петров Роман Алексеевич | N809: 2023-11-10 | S809: =T809&U809 -> Ткаченко Андрей ОлеговичВасильев Константин Дмитриевич | T809: Ткаченко Андрей Олегович | U809: Васильев Константин Дмитриевич | V809: 2024-06-27
K810: =L810&M810 -> Семенова Ирина ВалерьевнаЛебедева Ольга Романовна | L810: Семенова Ирина Валерьевна | M810: Лебедева Ольга Романовна | N810: 2023-11-10 | S810: =T810&U810 -> Сидорова Елена ВасильевнаСеменова Наталья Олеговна | T810: Сидорова Елена Васильевна | U810: Семенова Наталья Олеговна | V810: 2024-06-27
K811: =L811&M811 -> Новикова Ольга ПетровнаСидоров Михаил Сергеевич | L811: Новикова Ольга Петровна | M811: Сидоров Михаил Сергеевич | N811: 2023-11-10 | S811: =T811&U811 -> Яковлев Артем ИгоревичОрлов Андрей Никитич | T811: Яковлев Артем Игоревич | U811: Орлов Андрей Никитич | V811: 2024-06-28
K812: =L812&M812 -> Семенова Ирина ВалерьевнаСтепанов Константин Геннадьевич | L812: Семенова Ирина Валерьевна | M812: Степанов Константин Геннадьевич | N812: 2023-11-09 | S812: =T812&U812 -> Иванова Анна СергеевнаОрлова Анна Романовна | T812: Иванова Анна Сергеевна | U812: Орлова Анна Романовна | V812: 2024-06-28
K813: =L813&M813 -> Яковлев Артем ИгоревичПопов Никита Геннадьевич | L813: Яковлев Артем Игоревич | M813: Попов Никита Геннадьевич | N813: 2023-11-09 | S813: =T813&U813 -> Иванова Анна СергеевнаСтепанов Сергей Егорович | T813: Иванова Анна Сергеевна | U813: Степанов Сергей Егорович | V813: 2024-06-28
K814: =L814&M814 -> Фролов Сергей ВикторовичПопов Никита Геннадьевич | L814: Фролов Сергей Викторович | M814: Попов Никита Геннадьевич | N814: 2023-11-09 | S814: =T814&U814 -> Иванова Анна СергеевнаСтепанов Александр Андреевич | T814: Иванова Анна Сергеевна | U814: Степанов Александр Андреевич | V814: 2024-07-01
K815: =L815&M815 -> Ткаченко Андрей ОлеговичИванова Наталья Михайловна | L815: Ткаченко Андрей Олегович | M815: Иванова Наталья Михайловна | N815: 2023-11-08 | S815: =T815&U815 -> Фролов Сергей ВикторовичВолков Кирилл Юрьевич | T815: Фролов Сергей Викторович | U815: Волков Кирилл Юрьевич | V815: 2024-07-01
K816: =L816&M816 -> Орлов Павел ДенисовичСмирнова Людмила Олеговна | L816: Орлов Павел Денисович | M816: Смирнова Людмила Олеговна | N816: 2023-11-08 | S816: =T816&U816 -> Белов Алексей КонстантиновичСтепанова Ольга Андреевна | T816: Белов Алексей Константинович | U816: Степанова Ольга Андреевна | V816: 2024-07-01
K817: =L817&M817 -> Сидорова Елена ВасильевнаНовиков Егор Юрьевич | L817: Сидорова Елена Васильевна | M817: Новиков Егор Юрьевич | N817: 2023-11-08 | S817: =T817&U817 -> Белов Алексей КонстантиновичАлексеев Илья Владимирович | T817: Белов Алексей Константинович | U817: Алексеев Илья Владимирович | V817: 2024-07-01
K818: =L818&M818 -> Кузнецов Дмитрий ЛьвовичФедорова София Егоровна | L818: Кузнецов Дмитрий Львович | M818: Федорова София Егоровна | N818: 2023-11-08 | S818: =T818&U818 -> Громова Мария ИльиничнаСмирнов Максим Сергеевич | T818: Громова Мария Ильинична | U818: Смирнов Максим Сергеевич | V818: 2024-07-01
K819: =L819&M819 -> Новикова Ольга ПетровнаЕгорова Светлана Андреевна | L819: Новикова Ольга Петровна | M819: Егорова Светлана Андреевна | N819: 2023-11-08 | S819: =T819&U819 -> Фролов Сергей ВикторовичСидорова Полина Олеговна | T819: Фролов Сергей Викторович | U819: Сидорова Полина Олеговна | V819: 2024-07-01
... K1001: =L1001&M1001 -> Сидорова Елена ВасильевнаМорозов Егор Андреевич | L1001: Сидорова Елена Васильевна | M1001: Морозов Егор Андреевич | N1001: 2023-09-01 | S1001: =T1001&U1001 -> Ткаченко Андрей ОлеговичПопова Людмила Егоровна | T1001: Ткаченко Андрей Олегович | U1001: Попова Людмила Егоровна | V1001: 2024-09-02

Sheet Задача 1(2)
A1: ФИО менеджера | B1: ФИО клиента | C1: Дата первой сделки | D1: Дата последней сделки | E1: Дни
A2: Семенова Ирина Валерьевна | B2: Орлов Константин Станиславович | C2: 2023-09-04 | D2: 2024-08-29 | E2: 360 | M2: Названия строк | N2: Максимум по полю Дни
A3: Фролов Сергей Викторович | B3: Степанов Дмитрий Иванович | C3: 2023-09-18 | D3: 2024-08-30 | E3: 347 | M3: Белов Алексей Константинович | N3: 312
A4: Громова Мария Ильинична | B4: Николаев Матвей Викторович | C4: 2023-09-04 | D4: 2024-08-14 | E4: 345 | M4: Громова Мария Ильинична | N4: 345
A5: Фролов Сергей Викторович | B5: Семенова Светлана Дмитриевна | C5: 2023-09-08 | D5: 2024-08-16 | E5: 343 | M5: Иванова Анна Сергеевна | N5: 294
A6: Громова Мария Ильинична | B6: Лебедев Сергей Станиславович | C6: 2023-09-15 | D6: 2024-08-16 | E6: 336 | M6: Кузнецов Дмитрий Львович | N6: 303
A7: Фролов Сергей Викторович | B7: Петров Роман Алексеевич | C7: 2023-10-02 | D7: 2024-08-20 | E7: 323 | M7: Новикова Ольга Петровна | N7: 280
A8: Петров Владимир Кириллович | B8: Смирнов Иван Ильич | C8: 2023-10-05 | D8: 2024-08-23 | E8: 323 | M8: Орлов Павел Денисович | N8: 225
A9: Белов Алексей Константинович | B9: Егорова Алиса Михайловна | C9: 2023-10-05 | D9: 2024-08-12 | E9: 312 | M9: Петров Владимир Кириллович | N9: 323
A10: Фролов Сергей Викторович | B10: Смирнов Илья Олегович | C10: 2023-10-09 | D10: 2024-08-16 | E10: 312 | M10: Семенова Ирина Валерьевна | N10: 360
A11: Петров Владимир Кириллович | B11: Васильев Дмитрий Иванович | C11: 2023-10-12 | D11: 2024-08-12 | E11: 305 | M11: Сидорова Елена Васильевна | N11: 293
A12: Кузнецов Дмитрий Львович | B12: Орлова Анна Романовна | C12: 2023-09-11 | D12: 2024-07-10 | E12: 303 | M12: Ткаченко Андрей Олегович | N12: 295
A13: Яковлев Артем Игоревич | B13: Петрова Алиса Станиславовна | C13: 2023-10-04 | D13: 2024-07-26 | E13: 296 | M13: Фролов Сергей Викторович | N13: 347
A14: Ткаченко Андрей Олегович | B14: Петрова Елена Юрьевна | C14: 2023-10-05 | D14: 2024-07-26 | E14: 295 | M14: Яковлев Артем Игоревич | N14: 296
A15: Иванова Анна Сергеевна | B15: Новикова Виктория Александровна | C15: 2023-10-23 | D15: 2024-08-12 | E15: 294 | M15: (пусто)
A16: Сидорова Елена Васильевна | B16: Морозов Егор Андреевич | C16: 2023-09-01 | D16: 2024-06-20 | E16: 293 | M16: Общий итог | N16: 360
A17: Новикова Ольга Петровна | B17: Кузнецова Алиса Владимировна | C17: 2023-09-11 | D17: 2024-06-17 | E17: 280
A18: Громова Мария Ильинична | B18: Кузнецов Максим Алексеевич | C18: 2023-10-10 | D18: 2024-07-11 | E18: 275
A19: Иванова Анна Сергеевна | B19: Васильев Дмитрий Иванович | C19: 2023-10-09 | D19: 2024-07-09 | E19: 274
A20: Яковлев Артем Игоревич | B20: Павлов Сергей Артемович | C20: 2023-10-17 | D20: 2024-07-15 | E20: 272
A21: Яковлев Артем Игоревич | B21: Иванова Людмила Юрьевна | C21: 2023-10-19 | D21: 2024-07-16 | E21: 271
A22: Семенова Ирина Валерьевна | B22: Петров Алексей Юрьевич | C22: 2023-09-05 | D22: 2024-05-31 | E22: 269
A23: Сидорова Елена Васильевна | B23: Степанов Александр Дмитриевич | C23: 2023-10-20 | D23: 2024-07-12 | E23: 266
A24: Семенова Ирина Валерьевна | B24: Семенов Алексей Владимирович | C24: 2023-11-27 | D24: 2024-08-19 | E24: 266
A25: Фролов Сергей Викторович | B25: Кузнецова Валерия Дмитриевна | C25: 2023-12-06 | D25: 2024-08-28 | E25: 266
A26: Ткаченко Андрей Олегович | B26: Новиков Матвей Егорович | C26: 2023-11-21 | D26: 2024-08-12 | E26: 265
A27: Фролов Сергей Викторович | B27: Петров Михаил Кириллович | C27: 2023-10-09 | D27: 2024-06-26 | E27: 261
A28: Яковлев Артем Игоревич | B28: Лебедева Александра Дмитриевна | C28: 2023-12-06 | D28: 2024-08-14 | E28: 252
... A807: Ткаченко Андрей Олегович | B807: Попова Людмила Егоровна | C807: 2024-09-02 | D807: 2024-09-02 | E807: 0

Sheet Задача 2
A1: Названия строк | B1: Проекты | C1: Сумма по полю Сумма сделки | E1: Названия строк | F1: Проекты | G1: Сумма по полю Сумма сделки | H1: Количество по полю ФИО менеджера | J1: ФИО менеджера | K1: ФИО клиента | M1: Названия строк | N1: Количество по полю ФИО менеджера
A2: Алексеев Илья Владимирович | B2: 4 | C2: 160160 | E2: Алексеев Илья Владимирович | F2: 4 | G2: 160160 | H2: 4 | J2: Громова Мария Ильинична | K2: Волкова Валерия Алексеевна | M2: Алексеев Илья Владимирович | N2: 4
A3: Алексеев Кирилл Иванович | B3: 8 | C3: 432899 | E3: Алексеев Кирилл Иванович | F3: 8 | G3: 432899 | H3: 7 | J3: Сидорова Елена Васильевна | K3: Морозов Егор Андреевич | M3: Алексеев Кирилл Иванович | N3: 7
A4: Алексеев Кирилл Сергеевич | B4: 4 | C4: 180778 | E4: Алексеев Кирилл Сергеевич | F4: 4 | G4: 180778 | H4: 3 | J4: Семенова Ирина Валерьевна | K4: Орлов Константин Станиславович | M4: Алексеев Кирилл Сергеевич | N4: 3
A5: Васильев Артур Артемович | B5: 5 | C5: 266851 | E5: Васильев Артур Артемович | F5: 5 | G5: 266851 | H5: 4 | J5: Иванова Анна Сергеевна | K5: Иванова Наталья Дмитриевна | M5: Васильев Артур Артемович | N5: 4
A6: Васильев Владимир Дмитриевич | B6: 3 | C6: 141363 | E6: Васильев Владимир Дмитриевич | F6: 3 | G6: 141363 | H6: 2 | J6: Громова Мария Ильинична | K6: Николаев Матвей Викторович | M6: Васильев Владимир Дмитриевич | N6: 2
A7: Васильев Дмитрий Иванович | B7: 8 | C7: 401433 | E7: Васильев Дмитрий Иванович | F7: 8 | G7: 401433 | H7: 6 | J7: Фролов Сергей Викторович | K7: Козлова Полина Артемовна | M7: Васильев Дмитрий Иванович | N7: 6
A8: Васильев Иван Олегович | B8: 2 | C8: 66931 | E8: Васильев Иван Олегович | F8: 2 | G8: 66931 | H8: 2 | J8: Петров Владимир Кириллович | K8: Орлова Анна Романовна | M8: Васильев Иван Олегович | N8: 2
A9: Васильев Илья Александрович | B9: 6 | C9: 395057 | E9: Васильев Илья Александрович | F9: 6 | G9: 395057 | H9: 6 | J9: Петров Владимир Кириллович | K9: Лебедева Александра Дмитриевна | M9: Васильев Илья Александрович | N9: 6
A10: Васильев Константин Дмитриевич | B10: 6 | C10: 312620 | E10: Васильев Константин Дмитриевич | F10: 6 | G10: 312620 | H10: 5 | J10: Иванова Анна Сергеевна | K10: Волкова Ольга Андреевна | M10: Васильев Константин Дмитриевич | N10: 5
A11: Васильев Максим Иванович | B11: 4 | C11: 242415 | E11: Васильев Максим Иванович | F11: 4 | G11: 242415 | H11: 4 | J11: Семенова Ирина Валерьевна | K11: Петров Алексей Юрьевич | M11: Васильев Максим Иванович | N11: 4
A12: Васильева Ксения Михайловна | B12: 8 | C12: 425363 | E12: Васильева Ксения Михайловна | F12: 8 | G12: 425363 | H12: 5 | J12: Петров Владимир Кириллович | K12: Волкова Наталья Андреевна | M12: Васильева Ксения Михайловна | N12: 5
A13: Васильева Ольга Ильинична | B13: 2 | C13: 125362 | E13: Васильева Ольга Ильинична | F13: 2 | G13: 125362 | H13: 2 | J13: Белов Алексей Константинович | K13: Смирнов Илья Олегович | M13: Васильева Ольга Ильинична | N13: 2
... A194: Федорова София Егоровна | B194: 3 | C194: 96433 | E194: Федорова София Егоровна | F194: 3 | G194: 96433 | H194: 3 | J194: Яковлев Артем Игоревич | K194: Николаев Иван Михайлович | M194: Федорова София Егоровна | N194: 3
A195: (пусто) | E195: (пусто) | J195: Новикова Ольга Петровна | K195: Федорова Наталья Геннадьевна | M195: (пусто)
H196: 806 | J196: Иванова Анна Сергеевна | K196: Волкова Валерия Алексеевна | M196: Общий итог | N196: 806
J197: Фролов Сергей Викторович | K197: Орлов Роман Ильич
J198: Яковлев Артем Игоревич | K198: Семенов Иван Павлович
J199: Ткаченко Андрей Олегович | K199: Федоров Артур Олегович
J200: Громова Мария Ильинична | K200: Иванов Андрей Андреевич
J201: Ткаченко Андрей Олегович | K201: Смирнов Максим Сергеевич
J202: Яковлев Артем Игоревич | K202: Иванова Анна Егоровна
J203: Белов Алексей Константинович | K203: Семенов Павел Юрьевич
J204: Сидорова Елена Васильевна | K204: Волкова Ирина Сергеевна
J205: Иванова Анна Сергеевна | K205: Смирнова Татьяна Александровна
J206: Громова Мария Ильинична | K206: Николаев Георгий Сергеевич
J207: Новикова Ольга Петровна | K207: Федорова Ксения Павловна
J208: Громова Мария Ильинична | K208: Семенов Роман Павлович
... J807: Ткаченко Андрей Олегович | K807: Попова Людмила Егоровна

Sheet Задача 2_1
A1: ФИО клиента | B1: Дата сделки | C1: год | D1: месяц | E1: Год-месяц | H1: ФИО клиента | I1: Год-месяц | K1: ФИО клиента
A2: Волкова Валерия Алексеевна | B2: 2023-09-01 | C2: =YEAR(B2) -> 2023 | D2: =MONTH(B2) -> 9 | E2: =C2&"-"&D2 -> 2023-9 | H2: Алексеев Илья Владимирович | I2: 2024-3 | K2: Алексеев Илья Владимирович | L2: =COUNTIF(H:H,K2) -> 4
A3: Морозов Егор Андреевич | B3: 2023-09-01 | C3: =YEAR(B3) -> 2023 | D3: =MONTH(B3) -> 9 | E3: =C3&"-"&D3 -> 2023-9 | H3: Алексеев Илья Владимирович | I3: 2024-4 | K3: Алексеев Кирилл Иванович | L3: =COUNTIF(H:H,K3) -> 7
A4: Орлов Константин Станиславович | B4: 2023-09-04 | C4: =YEAR(B4) -> 2023 | D4: =MONTH(B4) -> 9 | E4: =C4&"-"&D4 -> 2023-9 | H4: Алексеев Илья Владимирович | I4: 2024-5 | K4: Алексеев Кирилл Сергеевич | L4: =COUNTIF(H:H,K4) -> 4
A5: Иванова Наталья Дмитриевна | B5: 2023-09-04 | C5: =YEAR(B5) -> 2023 | D5: =MONTH(B5) -> 9 | E5: =C5&"-"&D5 -> 2023-9 | H5: Алексеев Илья Владимирович | I5: 2024-7 | K5: Васильев Артур Артемович | L5: =COUNTIF(H:H,K5) -> 3
A6: Николаев Матвей Викторович | B6: 2023-09-04 | C6: =YEAR(B6) -> 2023 | D6: =MONTH(B6) -> 9 | E6: =C6&"-"&D6 -> 2023-9 | H6: Алексеев Кирилл Иванович | I6: 2023-9 | K6: Васильев Владимир Дмитриевич | L6: =COUNTIF(H:H,K6) -> 3
A7: Козлова Полина Артемовна | B7: 2023-09-04 | C7: =YEAR(B7) -> 2023 | D7: =MONTH(B7) -> 9 | E7: =C7&"-"&D7 -> 2023-9 | H7: Алексеев Кирилл Иванович | I7: 2023-10 | K7: Васильев Дмитрий Иванович | L7: =COUNTIF(H:H,K7) -> 7
A8: Орлова Анна Романовна | B8: 2023-09-04 | C8: =YEAR(B8) -> 2023 | D8: =MONTH(B8) -> 9 | E8: =C8&"-"&D8 -> 2023-9 | H8: Алексеев Кирилл Иванович | I8: 2023-11 | K8: Васильев Иван Олегович | L8: =COUNTIF(H:H,K8) -> 2
A9: Лебедева Александра Дмитриевна | B9: 2023-09-04 | C9: =YEAR(B9) -> 2023 | D9: =MONTH(B9) -> 9 | E9: =C9&"-"&D9 -> 2023-9 | H9: Алексеев Кирилл Иванович | I9: 2024-3 | K9: Васильев Илья Александрович | L9: =COUNTIF(H:H,K9) -> 4
A10: Волкова Ольга Андреевна | B10: 2023-09-04 | C10: =YEAR(B10) -> 2023 | D10: =MONTH(B10) -> 9 | E10: =C10&"-"&D10 -> 2023-9 | H10: Алексеев Кирилл Иванович | I10: 2024-6 | K10: Васильев Константин Дмитриевич | L10: =COUNTIF(H:H,K10) -> 5
A11: Петров Алексей Юрьевич | B11: 2023-09-05 | C11: =YEAR(B11) -> 2023 | D11: =MONTH(B11) -> 9 | E11: =C11&"-"&D11 -> 2023-9 | H11: Алексеев Кирилл Иванович | I11: 2024-7 | K11: Васильев Максим Иванович | L11: =COUNTIF(H:H,K11) -> 4
A12: Волкова Наталья Андреевна | B12: 2023-09-05 | C12: =YEAR(B12) -> 2023 | D12: =MONTH(B12) -> 9 | E12: =C12&"-"&D12 -> 2023-9 | H12: Алексеев Кирилл Иванович | I12: 2024-8 | K12: Васильева Ксения Михайловна | L12: =COUNTIF(H:H,K12) -> 6
A13: Смирнов Илья Олегович | B13: 2023-09-05 | C13: =YEAR(B13) -> 2023 | D13: =MONTH(B13) -> 9 | E13: =C13&"-"&D13 -> 2023-9 | H13: Алексеев Кирилл Сергеевич | I13: 2023-11 | K13: Васильева Ольга Ильинична | L13: =COUNTIF(H:H,K13) -> 2
... A194: Лебедева Ольга Романовна | B194: 2023-11-10 | C194: =YEAR(B194) -> 2023 | D194: =MONTH(B194) -> 11 | E194: =C194&"-"&D194 -> 2023-11 | H194: Козлов Павел Андреевич | I194: 2024-7 | K194: Федорова София Егоровна | L194: =COUNTIF(H:H,K194) -> 2
A195: Сидоров Михаил Сергеевич | B195: 2023-11-10 | C195: =YEAR(B195) -> 2023 | D195: =MONTH(B195) -> 11 | E195: =C195&"-"&D195 -> 2023-11 | H195: Козлова Ксения Ильинична | I195: 2023-10
A196: Семенов Константин Егорович | B196: 2023-11-13 | C196: =YEAR(B196) -> 2023 | D196: =MONTH(B196) -> 11 | E196: =C196&"-"&D196 -> 2023-11 | H196: Козлова Ксения Ильинична | I196: 2024-3
A197: Петрова Елена Юрьевна | B197: 2023-11-13 | C197: =YEAR(B197) -> 2023 | D197: =MONTH(B197) -> 11 | E197: =C197&"-"&D197 -> 2023-11 | H197: Козлова Ксения Ильинична | I197: 2024-4
A198: Николаев Иван Михайлович | B198: 2023-11-13 | C198: =YEAR(B198) -> 2023 | D198: =MONTH(B198) -> 11 | E198: =C198&"-"&D198 -> 2023-11 | H198: Козлова Ксения Ильинична | I198: 2024-5
A199: Федорова Наталья Геннадьевна | B199: 2023-11-13 | C199: =YEAR(B199) -> 2023 | D199: =MONTH(B199) -> 11 | E199: =C199&"-"&D199 -> 2023-11 | H199: Козлова Ксения Ильинична | I199: 2024-6
A200: Волкова Валерия Алексеевна | B200: 2023-11-13 | C200: =YEAR(B200) -> 2023 | D200: =MONTH(B200) -> 11 | E200: =C200&"-"&D200 -> 2023-11 | H200: Козлова Полина Артемовна | I200: 2023-9
A201: Орлов Роман Ильич | B201: 2023-11-13 | C201: =YEAR(B201) -> 2023 | D201: =MONTH(B201) -> 11 | E201: =C201&"-"&D201 -> 2023-11 | H201: Козлова Полина Артемовна | I201: 2023-10
A202: Семенов Иван Павлович | B202: 2023-11-13 | C202: =YEAR(B202) -> 2023 | D202: =MONTH(B202) -> 11 | E202: =C202&"-"&D202 -> 2023-11 | H202: Козлова Полина Артемовна | I202: 2023-11
A203: Федоров Артур Олегович | B203: 2023-11-13 | C203: =YEAR(B203) -> 2023 | D203: =MONTH(B203) -> 11 | E203: =C203&"-"&D203 -> 2023-11 | H203: Козлова Полина Артемовна | I203: 2024-1
A204: Иванов Андрей Андреевич | B204: 2023-11-13 | C204: =YEAR(B204) -> 2023 | D204: =MONTH(B204) -> 11 | E204: =C204&"-"&D204 -> 2023-11 | H204: Козлова Полина Артемовна | I204: 2024-3
A205: Смирнов Максим Сергеевич | B205: 2023-11-13 | C205: =YEAR(B205) -> 2023 | D205: =MONTH(B205) -> 11 | E205: =C205&"-"&D205 -> 2023-11 | H205: Козлова Светлана Михайловна | I205: 2024-1
A206: Иванова Анна Егоровна | B206: 2023-11-13 | C206: =YEAR(B206) -> 2023 | D206: =MONTH(B206) -> 11 | E206: =C206&"-"&D206 -> 2023-11 | H206: Козлова Светлана Михайловна | I206: 2024-2
... A815: Волков Кирилл Юрьевич | B815: 2024-07-01 | C815: =YEAR(B815) -> 2024 | D815: =MONTH(B815) -> 7 | E815: =C815&"-"&D815 -> 2024-7 | H815: Федорова София Егоровна | I815: 2024-8
A816: Степанова Ольга Андреевна | B816: 2024-07-01 | C816: =YEAR(B816) -> 2024 | D816: =MONTH(B816) -> 7 | E816: =C816&"-"&D816 -> 2024-7
A817: Алексеев Илья Владимирович | B817: 2024-07-01 | C817: =YEAR(B817) -> 2024 | D817: =MONTH(B817) -> 7 | E817: =C817&"-"&D817 -> 2024-7
A818: Смирнов Максим Сергеевич | B818: 2024-07-01 | C818: =YEAR(B818) -> 2024 | D818: =MONTH(B818) -> 7 | E818: =C818&"-"&D818 -> 2024-7
A819: Сидорова Полина Олеговна | B819: 2024-07-01 | C819: =YEAR(B819) -> 2024 | D819: =MONTH(B819) -> 7 | E819: =C819&"-"&D819 -> 2024-7
A820: Орлова Ольга Алексеевна | B820: 2024-07-01 | C820: =YEAR(B820) -> 2024 | D820: =MONTH(B820) -> 7 | E820: =C820&"-"&D820 -> 2024-7
A821: Семенов Иван Павлович | B821: 2024-07-01 | C821: =YEAR(B821) -> 2024 | D821: =MONTH(B821) -> 7 | E821: =C821&"-"&D821 -> 2024-7
A822: Лебедев Матвей Сергеевич | B822: 2024-07-01 | C822: =YEAR(B822) -> 2024 | D822: =MONTH(B822) -> 7 | E822: =C822&"-"&D822 -> 2024-7
A823: Федорова Алиса Юрьевна | B823: 2024-07-01 | C823: =YEAR(B823) -> 2024 | D823: =MONTH(B823) -> 7 | E823: =C823&"-"&D823 -> 2024-7
A824: Николаев Иван Сергеевич | B824: 2024-07-02 | C824: =YEAR(B824) -> 2024 | D824: =MONTH(B824) -> 7 | E824: =C824&"-"&D824 -> 2024-7
A825: Степанова Полина Михайловна | B825: 2024-07-02 | C825: =YEAR(B825) -> 2024 | D825: =MONTH(B825) -> 7 | E825: =C825&"-"&D825 -> 2024-7
A826: Волков Максим Дмитриевич | B826: 2024-07-02 | C826: =YEAR(B826) -> 2024 | D826: =MONTH(B826) -> 7 | E826: =C826&"-"&D826 -> 2024-7
A827: Петрова Александра Олеговна | B827: 2024-07-02 | C827: =YEAR(B827) -> 2024 | D827: =MONTH(B827) -> 7 | E827: =C827&"-"&D827 -> 2024-7
... A1001: Попова Людмила Егоровна | B1001: 2024-09-02 | C1001: =YEAR(B1001) -> 2024 | D1001: =MONTH(B1001) -> 9 | E1001: =C1001&"-"&D1001 -> 2024-9

Sheet Задача 3_1
B1: 2023-9 | C1: 2023-10 | D1: 2023-11 | E1: 2023-12 | F1: 2024-1 | G1: 2024-2 | H1: 2024-3 | I1: 2024-4 | J1: 2024-5 | K1: 2024-6 | L1: 2024-7 | M1: 2024-8 | N1: 2024-9 | P1: ФИО менеджера | Q1: ФИО клиента | R1: Дата сделки | S1: Сумма сделки | T1: NPS | U1: Месяц | V1: Год | W1: Год-месяц
A2: Белов Алексей Константинович | P2: Громова Мария Ильинична | Q2: Волкова Валерия Алексеевна | R2: 2023-09-01 | S2: 49585 | T2: 5 | U2: =MONTH(R2) -> 9 | V2: =YEAR(R2) -> 2023 | W2: =V2&"-"&U2 -> 2023-9
A3: Громова Мария Ильинична | P3: Сидорова Елена Васильевна | Q3: Морозов Егор Андреевич | R3: 2023-09-01 | S3: 70374 | T3: 1 | U3: =MONTH(R3) -> 9 | V3: =YEAR(R3) -> 2023 | W3: =V3&"-"&U3 -> 2023-9
A4: Иванова Анна Сергеевна | P4: Семенова Ирина Валерьевна | Q4: Орлов Константин Станиславович | R4: 2023-09-04 | S4: 17347 | T4: 8 | U4: =MONTH(R4) -> 9 | V4: =YEAR(R4) -> 2023 | W4: =V4&"-"&U4 -> 2023-9
A5: Кузнецов Дмитрий Львович | P5: Иванова Анна Сергеевна | Q5: Иванова Наталья Дмитриевна | R5: 2023-09-04 | S5: 77152 | T5: 10 | U5: =MONTH(R5) -> 9 | V5: =YEAR(R5) -> 2023 | W5: =V5&"-"&U5 -> 2023-9
A6: Новикова Ольга Петровна | P6: Громова Мария Ильинична | Q6: Николаев Матвей Викторович | R6: 2023-09-04 | S6: 25583 | T6: 7 | U6: =MONTH(R6) -> 9 | V6: =YEAR(R6) -> 2023 | W6: =V6&"-"&U6 -> 2023-9
A7: Орлов Павел Денисович | P7: Фролов Сергей Викторович | Q7: Козлова Полина Артемовна | R7: 2023-09-04 | S7: 50424 | T7: 3 | U7: =MONTH(R7) -> 9 | V7: =YEAR(R7) -> 2023 | W7: =V7&"-"&U7 -> 2023-9
A8: Петров Владимир Кириллович | P8: Петров Владимир Кириллович | Q8: Орлова Анна Романовна | R8: 2023-09-04 | S8: 27772 | T8: 1 | U8: =MONTH(R8) -> 9 | V8: =YEAR(R8) -> 2023 | W8: =V8&"-"&U8 -> 2023-9
A9: Семенова Ирина Валерьевна | P9: Петров Владимир Кириллович | Q9: Лебедева Александра Дмитриевна | R9: 2023-09-04 | S9: 58246 | T9: 8 | U9: =MONTH(R9) -> 9 | V9: =YEAR(R9) -> 2023 | W9: =V9&"-"&U9 -> 2023-9
A10: Сидорова Елена Васильевна | P10: Иванова Анна Сергеевна | Q10: Волкова Ольга Андреевна | R10: 2023-09-04 | S10: 30493 | T10: 4 | U10: =MONTH(R10) -> 9 | V10: =YEAR(R10) -> 2023 | W10: =V10&"-"&U10 -> 2023-9
A11: Ткаченко Андрей Олегович | P11: Семенова Ирина Валерьевна | Q11: Петров Алексей Юрьевич | R11: 2023-09-05 | S11: 66366 | T11: 4 | U11: =MONTH(R11) -> 9 | V11: =YEAR(R11) -> 2023 | W11: =V11&"-"&U11 -> 2023-9
A12: Фролов Сергей Викторович | P12: Петров Владимир Кириллович | Q12: Волкова Наталья Андреевна | R12: 2023-09-05 | S12: 25078 | T12: 6 | U12: =MONTH(R12) -> 9 | V12: =YEAR(R12) -> 2023 | W12: =V12&"-"&U12 -> 2023-9
A13: Яковлев Артем Игоревич | P13: Белов Алексей Константинович | Q13: Смирнов Илья Олегович | R13: 2023-09-05 | S13: 75327 | T13: 8 | U13: =MONTH(R13) -> 9 | V13: =YEAR(R13) -> 2023 | W13: =V13&"-"&U13 -> 2023-9
P14: Ткаченко Андрей Олегович | Q14: Козлова Татьяна Сергеевна | R14: 2023-09-06 | S14: 68907 | T14: 3 | U14: =MONTH(R14) -> 9 | V14: =YEAR(R14) -> 2023 | W14: =V14&"-"&U14 -> 2023-9
P15: Яковлев Артем Игоревич | Q15: Васильев Артур Артемович | R15: 2023-09-06 | S15: 61980 | T15: 6 | U15: =MONTH(R15) -> 9 | V15: =YEAR(R15) -> 2023 | W15: =V15&"-"&U15 -> 2023-9
P16: Иванова Анна Сергеевна | Q16: Сидоров Владимир Артемович | R16: 2023-09-06 | S16: 63884 | T16: 7 | U16: =MONTH(R16) -> 9 | V16: =YEAR(R16) -> 2023 | W16: =V16&"-"&U16 -> 2023-9
P17: Белов Алексей Константинович | Q17: Новиков Матвей Егорович | R17: 2023-09-07 | S17: 35787 | T17: 1 | U17: =MONTH(R17) -> 9 | V17: =YEAR(R17) -> 2023 | W17: =V17&"-"&U17 -> 2023-9
P18: Фролов Сергей Викторович | Q18: Лебедева Александра Дмитриевна | R18: 2023-09-07 | S18: 28370 | T18: 9 | U18: =MONTH(R18) -> 9 | V18: =YEAR(R18) -> 2023 | W18: =V18&"-"&U18 -> 2023-9
P19: Фролов Сергей Викторович | Q19: Семенов Алексей Владимирович | R19: 2023-09-07 | S19: 37951 | T19: 0 | U19: =MONTH(R19) -> 9 | V19: =YEAR(R19) -> 2023 | W19: =V19&"-"&U19 -> 2023-9
P20: Сидорова Елена Васильевна | Q20: Павлов Никита Иванович | R20: 2023-09-07 | S20: 39832 | T20: 7 | U20: =MONTH(R20) -> 9 | V20: =YEAR(R20) -> 2023 | W20: =V20&"-"&U20 -> 2023-9
P21: Сидорова Елена Васильевна | Q21: Смирнов Константин Кириллович | R21: 2023-09-07 | S21: 18687 | T21: 7 | U21: =MONTH(R21) -> 9 | V21: =YEAR(R21) -> 2023 | W21: =V21&"-"&U21 -> 2023-9
P22: Кузнецов Дмитрий Львович | Q22: Смирнова Татьяна Александровна | R22: 2023-09-08 | S22: 69529 | T22: 8 | U22: =MONTH(R22) -> 9 | V22: =YEAR(R22) -> 2023 | W22: =V22&"-"&U22 -> 2023-9
P23: Фролов Сергей Викторович | Q23: Семенова Светлана Дмитриевна | R23: 2023-09-08 | S23: 59076 | T23: 6 | U23: =MONTH(R23) -> 9 | V23: =YEAR(R23) -> 2023 | W23: =V23&"-"&U23 -> 2023-9
P24: Петров Владимир Кириллович | Q24: Кузнецова Мария Дмитриевна | R24: 2023-09-08 | S24: 87820 | T24: 6 | U24: =MONTH(R24) -> 9 | V24: =YEAR(R24) -> 2023 | W24: =V24&"-"&U24 -> 2023-9
P25: Петров Владимир Кириллович | Q25: Федорова Наталья Геннадьевна | R25: 2023-09-11 | S25: 30927 | T25: 6 | U25: =MONTH(R25) -> 9 | V25: =YEAR(R25) -> 2023 | W25: =V25&"-"&U25 -> 2023-9
... P1001: Ткаченко Андрей Олегович | Q1001: Попова Людмила Егоровна | R1001: 2024-09-02 | S1001: 80783 | T1001: 6 | U1001: =MONTH(R1001) -> 9 | V1001: =YEAR(R1001) -> 2024 | W1001: =V1001&"-"&U1001 -> 2024-9

Sheet Задача 3_2
B1: 2023-9 | C1: 2023-10 | D1: 2023-11 | E1: 2023-12 | F1: 2024-1 | G1: 2024-2 | H1: 2024-3 | I1: 2024-4 | J1: 2024-5 | K1: 2024-6 | L1: 2024-7 | M1: 2024-8 | N1: 2024-9 | R1: ФИО менеджера | S1: ФИО клиента | T1: Дата сделки | U1: Сумма сделки | V1: NPS | W1: Месяц | X1: Год | Y1: Год-месяц
A2: Белов Алексей Константинович | B2: =(COUNTIFS($R$2:$R$1001,$A2,$Y$2:$Y$1001,B$1,$V$2:$V$1001,">=9") - (COUNTIFS($R$2:$R$1001,$A2,$Y$2:$Y$1001,B$1,$V$2:$V$1001,"<=6"))) / COUNTIFS($R$2:$R$1001,$A2,$Y$2:$Y$1001,B$1,$V$2:$V$1001,">0") -> -0.2 | C2: =(COUNTIFS($R$2:$R$1001,$A2,$Y$2:$Y$1001,C$1,$V$2:$V$1001,">=9") - (COUNTIFS($R$2:$R$1001,$A2,$Y$2:$Y$1001,C$1,$V$2:$V$1001,"<=6"))) / COUNTIFS($R$2:$R$1001,$A2,$Y$2:$Y$1001,C$1,$V$2:$V$1001,">0") -> 0.16666667 | D2: =(COUNTIFS($R$2:$R$1001,$A2,$Y$2:$Y$1001,D$1,$V$2:$V$1001,">=9") - (COUNTIFS($R$2:$R$1001,$A2,$Y$2:$Y$1001,D$1,$V$2:$V$1001,"<=6"))) / COUNTIFS($R$2:$R$1001,$A2,$Y$2:$Y$1001,D$1,$V$2:$V$1001,">0") -> -0.33333333 | E2: =(COUNTIFS($R$2:$R$1001,$A2,$Y$2:$Y$1001,E$1,$V$2:$V$1001,">=9") - (COUNTIFS($R$2:$R$1001,$A2,$Y$2:$Y$1001,E$1,$V$2:$V$1001,"<=6"))) / COUNTIFS($R$2:$R$1001,$A2,$Y$2:$Y$1001,E$1,$V$2:$V$1001,">0") -> -0.11111111 | F2: =(COUNTIFS($R$2:$R$1001,$A2,$Y$2:$Y$1001,F$1,$V$2:$V$1001,">=9") - (COUNTIFS($R$2:$R$1001,$A2,$Y$2:$Y$1001,F$1,$V$2:$V$1001,"<=6"))) / COUNTIFS($R$2:$R$1001,$A2,$Y$2:$Y$1001,F$1,$V$2:$V$1001,">0") -> -0.42857143 | G2: =(COUNTIFS($R$2:$R$1001,$A2,$Y$2:$Y$1001,G$1,$V$2:$V$1001,">=9") - (COUNTIFS($R$2:$R$1001,$A2,$Y$2:$Y$1001,G$1,$V$2:$V$1001,"<=6"))) / COUNTIFS($R$2:$R$1001,$A2,$Y$2:$Y$1001,G$1,$V$2:$V$1001,">0") -> -0.75 | H2: =(COUNTIFS($R$2:$R$1001,$A2,$Y$2:$Y$1001,H$1,$V$2:$V$1001,">=9") - (COUNTIFS($R$2:$R$1001,$A2,$Y$2:$Y$1001,H$1,$V$2:$V$1001,"<=6"))) / COUNTIFS($R$2:$R$1001,$A2,$Y$2:$Y$1001,H$1,$V$2:$V$1001,">0") -> -0.42857143 | I2: =(COUNTIFS($R$2:$R$1001,$A2,$Y$2:$Y$1001,I$1,$V$2:$V$1001,">=9") - (COUNTIFS($R$2:$R$1001,$A2,$Y$2:$Y$1001,I$1,$V$2:$V$1001,"<=6"))) / COUNTIFS($R$2:$R$1001,$A2,$Y$2:$Y$1001,I$1,$V$2:$V$1001,">0") -> -0.6 | ... N2: =(COUNTIFS($R$2:$R$1001,$A2,$Y$2:$Y$1001,N$1,$V$2:$V$1001,">=9") - (COUNTIFS($R$2:$R$1001,$A2,$Y$2:$Y$1001,N$1,$V$2:$V$1001,"<=6"))) / COUNTIFS($R$2:$R$1001,$A2,$Y$2:$Y$1001,N$1,$V$2:$V$1001,">0") -> #DIV/0! | R2: Белов Алексей Константинович | S2: Смирнов Илья Олегович | T2: 2023-09-05 | U2: 75327 | V2: 8 | W2: =MONTH(T2) -> 9 | X2: =YEAR(T2) -> 2023 | Y2: =X2&"-"&W2 -> 2023-9
A3: Громова Мария Ильинична | B3: =(COUNTIFS($R$2:$R$1001,$A3,$Y$2:$Y$1001,B$1,$V$2:$V$1001,">=9") - (COUNTIFS($R$2:$R$1001,$A3,$Y$2:$Y$1001,B$1,$V$2:$V$1001,"<=6"))) / COUNTIFS($R$2:$R$1001,$A3,$Y$2:$Y$1001,B$1,$V$2:$V$1001,">0") -> -0.14285714 | C3: =(COUNTIFS($R$2:$R$1001,$A3,$Y$2:$Y$1001,C$1,$V$2:$V$1001,">=9") - (COUNTIFS($R$2:$R$1001,$A3,$Y$2:$Y$1001,C$1,$V$2:$V$1001,"<=6"))) / COUNTIFS($R$2:$R$1001,$A3,$Y$2:$Y$1001,C$1,$V$2:$V$1001,">0") -> -0.55555556 | D3: =(COUNTIFS($R$2:$R$1001,$A3,$Y$2:$Y$1001,D$1,$V$2:$V$1001,">=9") - (COUNTIFS($R$2:$R$1001,$A3,$Y$2:$Y$1001,D$1,$V$2:$V$1001,"<=6"))) / COUNTIFS($R$2:$R$1001,$A3,$Y$2:$Y$1001,D$1,$V$2:$V$1001,">0") -> -0.5 | E3: =(COUNTIFS($R$2:$R$1001,$A3,$Y$2:$Y$1001,E$1,$V$2:$V$1001,">=9") - (COUNTIFS($R$2:$R$1001,$A3,$Y$2:$Y$1001,E$1,$V$2:$V$1001,"<=6"))) / COUNTIFS($R$2:$R$1001,$A3,$Y$2:$Y$1001,E$1,$V$2:$V$1001,">0") -> -0.4 | F3: =(COUNTIFS($R$2:$R$1001,$A3,$Y$2:$Y$1001,F$1,$V$2:$V$1001,">=9") - (COUNTIFS($R$2:$R$1001,$A3,$Y$2:$Y$1001,F$1,$V$2:$V$1001,"<=6"))) / COUNTIFS($R$2:$R$1001,$A3,$Y$2:$Y$1001,F$1,$V$2:$V$1001,">0") -> 0 | G3: =(COUNTIFS($R$2:$R$1001,$A3,$Y$2:$Y$1001,G$1,$V$2:$V$1001,">=9") - (COUNTIFS($R$2:$R$1001,$A3,$Y$2:$Y$1001,G$1,$V$2:$V$1001,"<=6"))) / COUNTIFS($R$2:$R$1001,$A3,$Y$2:$Y$1001,G$1,$V$2:$V$1001,">0") -> -0.4 | H3: =(COUNTIFS($R$2:$R$1001,$A3,$Y$2:$Y$1001,H$1,$V$2:$V$1001,">=9") - (COUNTIFS($R$2:$R$1001,$A3,$Y$2:$Y$1001,H$1,$V$2:$V$1001,"<=6"))) / COUNTIFS($R$2:$R$1001,$A3,$Y$2:$Y$1001,H$1,$V$2:$V$1001,">0") -> -0.45454545 | I3: =(COUNTIFS($R$2:$R$1001,$A3,$Y$2:$Y$1001,I$1,$V$2:$V$1001,">=9") - (COUNTIFS($R$2:$R$1001,$A3,$Y$2:$Y$1001,I$1,$V$2:$V$1001,"<=6"))) / COUNTIFS($R$2:$R$1001,$A3,$Y$2:$Y$1001,I$1,$V$2:$V$1001,">0") -> 0 | ... N3: =(COUNTIFS($R$2:$R$1001,$A3,$Y$2:$Y$1001,N$1,$V$2:$V$1001,">=9") - (COUNTIFS($R$2:$R$1001,$A3,$Y$2:$Y$1001,N$1,$V$2:$V$1001,"<=6"))) / COUNTIFS($R$2:$R$1001,$A3,$Y$2:$Y$1001,N$1,$V$2:$V$1001,">0") -> #DIV/0! | R3: Белов Алексей Константинович | S3: Новиков Матвей Егорович | T3: 2023-09-07 | U3: 35787 | V3: 1 | W3: =MONTH(T3) -> 9 | X3: =YEAR(T3) -> 2023 | Y3: =X3&"-"&W3 -> 2023-9
A4: Иванова Анна Сергеевна | B4: =(COUNTIFS($R$2:$R$1001,$A4,$Y$2:$Y$1001,B$1,$V$2:$V$1001,">=9") - (COUNTIFS($R$2:$R$1001,$A4,$Y$2:$Y$1001,B$1,$V$2:$V$1001,"<=6"))) / COUNTIFS($R$2:$R$1001,$A4,$Y$2:$Y$1001,B$1,$V$2:$V$1001,">0") -> 0.16666667 | C4: =(COUNTIFS($R$2:$R$1001,$A4,$Y$2:$Y$1001,C$1,$V$2:$V$1001,">=9") - (COUNTIFS($R$2:$R$1001,$A4,$Y$2:$Y$1001,C$1,$V$2:$V$1001,"<=6"))) / COUNTIFS($R$2:$R$1001,$A4,$Y$2:$Y$1001,C$1,$V$2:$V$1001,">0") -> -0.18181818 | D4: =(COUNTIFS($R$2:$R$1001,$A4,$Y$2:$Y$1001,D$1,$V$2:$V$1001,">=9") - (COUNTIFS($R$2:$R$1001,$A4,$Y$2:$Y$1001,D$1,$V$2:$V$1001,"<=6"))) / COUNTIFS($R$2:$R$1001,$A4,$Y$2:$Y$1001,D$1,$V$2:$V$1001,">0") -> -0.2 | E4: =(COUNTIFS($R$2:$R$1001,$A4,$Y$2:$Y$1001,E$1,$V$2:$V$1001,">=9") - (COUNTIFS($R$2:$R$1001,$A4,$Y$2:$Y$1001,E$1,$V$2:$V$1001,"<=6"))) / COUNTIFS($R$2:$R$1001,$A4,$Y$2:$Y$1001,E$1,$V$2:$V$1001,">0") -> -0.5 | F4: =(COUNTIFS($R$2:$R$1001,$A4,$Y$2:$Y$1001,F$1,$V$2:$V$1001,">=9") - (COUNTIFS($R$2:$R$1001,$A4,$Y$2:$Y$1001,F$1,$V$2:$V$1001,"<=6"))) / COUNTIFS($R$2:$R$1001,$A4,$Y$2:$Y$1001,F$1,$V$2:$V$1001,">0") -> -0.5 | G4: =(COUNTIFS($R$2:$R$1001,$A4,$Y$2:$Y$1001,G$1,$V$2:$V$1001,">=9") - (COUNTIFS($R$2:$R$1001,$A4,$Y$2:$Y$1001,G$1,$V$2:$V$1001,"<=6"))) / COUNTIFS($R$2:$R$1001,$A4,$Y$2:$Y$1001,G$1,$V$2:$V$1001,">0") -> -0.5 | H4: =(COUNTIFS($R$2:$R$1001,$A4,$Y$2:$Y$1001,H$1,$V$2:$V$1001,">=9") - (COUNTIFS($R$2:$R$1001,$A4,$Y$2:$Y$1001,H$1,$V$2:$V$1001,"<=6"))) / COUNTIFS($R$2:$R$1001,$A4,$Y$2:$Y$1001,H$1,$V$2:$V$1001,">0") -> -0.66666667 | I4: =(COUNTIFS($R$2:$R$1001,$A4,$Y$2:$Y$1001,I$1,$V$2:$V$1001,">=9") - (COUNTIFS($R$2:$R$1001,$A4,$Y$2:$Y$1001,I$1,$V$2:$V$1001,"<=6"))) / COUNTIFS($R$2:$R$1001,$A4,$Y$2:$Y$1001,I$1,$V$2:$V$1001,">0") -> -0.66666667 | ... N4: =(COUNTIFS($R$2:$R$1001,$A4,$Y$2:$Y$1001,N$1,$V$2:$V$1001,">=9") - (COUNTIFS($R$2:$R$1001,$A4,$Y$2:$Y$1001,N$1,$V$2:$V$1001,"<=6"))) / COUNTIFS($R$2:$R$1001,$A4,$Y$2:$Y$1001,N$1,$V$2:$V$1001,">0") -> #DIV/0! | R4: Белов Алексей Константинович | S4: Васильева Ксения Михайловна | T4: 2023-09-14 | U4: 48097 | V4: 9 | W4: =MONTH(T4) -> 9 | X4: =YEAR(T4) -> 2023 | Y4: =X4&"-"&W4 -> 2023-9
A5: Кузнецов Дмитрий Львович | B5: =(COUNTIFS($R$2:$R$1001,$A5,$Y$2:$Y$1001,B$1,$V$2:$V$1001,">=9") - (COUNTIFS($R$2:$R$1001,$A5,$Y$2:$Y$1001,B$1,$V$2:$V$1001,"<=6"))) / COUNTIFS($R$2:$R$1001,$A5,$Y$2:$Y$1001,B$1,$V$2:$V$1001,">0") -> 0 | C5: =(COUNTIFS($R$2:$R$1001,$A5,$Y$2:$Y$1001,C$1,$V$2:$V$1001,">=9") - (COUNTIFS($R$2:$R$1001,$A5,$Y$2:$Y$1001,C$1,$V$2:$V$1001,"<=6"))) / COUNTIFS($R$2:$R$1001,$A5,$Y$2:$Y$1001,C$1,$V$2:$V$1001,">0") -> -0.5 | D5: =(COUNTIFS($R$2:$R$1001,$A5,$Y$2:$Y$1001,D$1,$V$2:$V$1001,">=9") - (COUNTIFS($R$2:$R$1001,$A5,$Y$2:$Y$1001,D$1,$V$2:$V$1001,"<=6"))) / COUNTIFS($R$2:$R$1001,$A5,$Y$2:$Y$1001,D$1,$V$2:$V$1001,">0") -> -0.5 | E5: =(COUNTIFS($R$2:$R$1001,$A5,$Y$2:$Y$1001,E$1,$V$2:$V$1001,">=9") - (COUNTIFS($R$2:$R$1001,$A5,$Y$2:$Y$1001,E$1,$V$2:$V$1001,"<=6"))) / COUNTIFS($R$2:$R$1001,$A5,$Y$2:$Y$1001,E$1,$V$2:$V$1001,">0") -> -0.5 | F5: =(COUNTIFS($R$2:$R$1001,$A5,$Y$2:$Y$1001,F$1,$V$2:$V$1001,">=9") - (COUNTIFS($R$2:$R$1001,$A5,$Y$2:$Y$1001,F$1,$V$2:$V$1001,"<=6"))) / COUNTIFS($R$2:$R$1001,$A5,$Y$2:$Y$1001,F$1,$V$2:$V$1001,">0") -> -0.8 | G5: =(COUNTIFS($R$2:$R$1001,$A5,$Y$2:$Y$1001,G$1,$V$2:$V$1001,">=9") - (COUNTIFS($R$2:$R$1001,$A5,$Y$2:$Y$1001,G$1,$V$2:$V$1001,"<=6"))) / COUNTIFS($R$2:$R$1001,$A5,$Y$2:$Y$1001,G$1,$V$2:$V$1001,">0") -> -1 | H5: =(COUNTIFS($R$2:$R$1001,$A5,$Y$2:$Y$1001,H$1,$V$2:$V$1001,">=9") - (COUNTIFS($R$2:$R$1001,$A5,$Y$2:$Y$1001,H$1,$V$2:$V$1001,"<=6"))) / COUNTIFS($R$2:$R$1001,$A5,$Y$2:$Y$1001,H$1,$V$2:$V$1001,">0") -> -0.5 | I5: =(COUNTIFS($R$2:$R$1001,$A5,$Y$2:$Y$1001,I$1,$V$2:$V$1001,">=9") - (COUNTIFS($R$2:$R$1001,$A5,$Y$2:$Y$1001,I$1,$V$2:$V$1001,"<=6"))) / COUNTIFS($R$2:$R$1001,$A5,$Y$2:$Y$1001,I$1,$V$2:$V$1001,">0") -> -0.66666667 | ... N5: =(COUNTIFS($R$2:$R$1001,$A5,$Y$2:$Y$1001,N$1,$V$2:$V$1001,">=9") - (COUNTIFS($R$2:$R$1001,$A5,$Y$2:$Y$1001,N$1,$V$2:$V$1001,"<=6"))) / COUNTIFS($R$2:$R$1001,$A5,$Y$2:$Y$1001,N$1,$V$2:$V$1001,">0") -> #DIV/0! | R5: Белов Алексей Константинович | S5: Волкова Татьяна Станиславовна | T5: 2023-09-25 | U5: 92084 | V5: 4 | W5: =MONTH(T5) -> 9 | X5: =YEAR(T5) -> 2023 | Y5: =X5&"-"&W5 -> 2023-9
A6: Новикова Ольга Петровна | B6: =(COUNTIFS($R$2:$R$1001,$A6,$Y$2:$Y$1001,B$1,$V$2:$V$1001,">=9") - (COUNTIFS($R$2:$R$1001,$A6,$Y$2:$Y$1001,B$1,$V$2:$V$1001,"<=6"))) / COUNTIFS($R$2:$R$1001,$A6,$Y$2:$Y$1001,B$1,$V$2:$V$1001,">0") -> 0 | C6: =(COUNTIFS($R$2:$R$1001,$A6,$Y$2:$Y$1001,C$1,$V$2:$V$1001,">=9") - (COUNTIFS($R$2:$R$1001,$A6,$Y$2:$Y$1001,C$1,$V$2:$V$1001,"<=6"))) / COUNTIFS($R$2:$R$1001,$A6,$Y$2:$Y$1001,C$1,$V$2:$V$1001,">0") -> -0.71428571 | D6: =(COUNTIFS($R$2:$R$1001,$A6,$Y$2:$Y$1001,D$1,$V$2:$V$1001,">=9") - (COUNTIFS($R$2:$R$1001,$A6,$Y$2:$Y$1001,D$1,$V$2:$V$1001,"<=6"))) / COUNTIFS($R$2:$R$1001,$A6,$Y$2:$Y$1001,D$1,$V$2:$V$1001,">0") -> -0.5 | E6: =(COUNTIFS($R$2:$R$1001,$A6,$Y$2:$Y$1001,E$1,$V$2:$V$1001,">=9") - (COUNTIFS($R$2:$R$1001,$A6,$Y$2:$Y$1001,E$1,$V$2:$V$1001,"<=6"))) / COUNTIFS($R$2:$R$1001,$A6,$Y$2:$Y$1001,E$1,$V$2:$V$1001,">0") -> -0.5 | F6: =(COUNTIFS($R$2:$R$1001,$A6,$Y$2:$Y$1001,F$1,$V$2:$V$1001,">=9") - (COUNTIFS($R$2:$R$1001,$A6,$Y$2:$Y$1001,F$1,$V$2:$V$1001,"<=6"))) / COUNTIFS($R$2:$R$1001,$A6,$Y$2:$Y$1001,F$1,$V$2:$V$1001,">0") -> 0.125 | G6: =(COUNTIFS($R$2:$R$1001,$A6,$Y$2:$Y$1001,G$1,$V$2:$V$1001,">=9") - (COUNTIFS($R$2:$R$1001,$A6,$Y$2:$Y$1001,G$1,$V$2:$V$1001,"<=6"))) / COUNTIFS($R$2:$R$1001,$A6,$Y$2:$Y$1001,G$1,$V$2:$V$1001,">0") -> -0.45454545 | H6: =(COUNTIFS($R$2:$R$1001,$A6,$Y$2:$Y$1001,H$1,$V$2:$V$1001,">=9") - (COUNTIFS($R$2:$R$1001,$A6,$Y$2:$Y$1001,H$1,$V$2:$V$1001,"<=6"))) / COUNTIFS($R$2:$R$1001,$A6,$Y$2:$Y$1001,H$1,$V$2:$V$1001,">0") -> -0.83333333 | I6: =(COUNTIFS($R$2:$R$1001,$A6,$Y$2:$Y$1001,I$1,$V$2:$V$1001,">=9") - (COUNTIFS($R$2:$R$1001,$A6,$Y$2:$Y$1001,I$1,$V$2:$V$1001,"<=6"))) / COUNTIFS($R$2:$R$1001,$A6,$Y$2:$Y$1001,I$1,$V$2:$V$1001,">0") -> -0.75 | ... N6: =(COUNTIFS($R$2:$R$1001,$A6,$Y$2:$Y$1001,N$1,$V$2:$V$1001,">=9") - (COUNTIFS($R$2:$R$1001,$A6,$Y$2:$Y$1001,N$1,$V$2:$V$1001,"<=6"))) / COUNTIFS($R$2:$R$1001,$A6,$Y$2:$Y$1001,N$1,$V$2:$V$1001,">0") -> 1 | R6: Белов Алексей Константинович | S6: Иванов Роман Кириллович | T6: 2023-09-25 | U6: 53861 | V6: 8 | W6: =MONTH(T6) -> 9 | X6: =YEAR(T6) -> 2023 | Y6: =X6&"-"&W6 -> 2023-9
A7: Орлов Павел Денисович | B7: =(COUNTIFS($R$2:$R$1001,$A7,$Y$2:$Y$1001,B$1,$V$2:$V$1001,">=9") - (COUNTIFS($R$2:$R$1001,$A7,$Y$2:$Y$1001,B$1,$V$2:$V$1001,"<=6"))) / COUNTIFS($R$2:$R$1001,$A7,$Y$2:$Y$1001,B$1,$V$2:$V$1001,">0") -> -1 | C7: =(COUNTIFS($R$2:$R$1001,$A7,$Y$2:$Y$1001,C$1,$V$2:$V$1001,">=9") - (COUNTIFS($R$2:$R$1001,$A7,$Y$2:$Y$1001,C$1,$V$2:$V$1001,"<=6"))) / COUNTIFS($R$2:$R$1001,$A7,$Y$2:$Y$1001,C$1,$V$2:$V$1001,">0") -> -0.33333333 | D7: =(COUNTIFS($R$2:$R$1001,$A7,$Y$2:$Y$1001,D$1,$V$2:$V$1001,">=9") - (COUNTIFS($R$2:$R$1001,$A7,$Y$2:$Y$1001,D$1,$V$2:$V$1001,"<=6"))) / COUNTIFS($R$2:$R$1001,$A7,$Y$2:$Y$1001,D$1,$V$2:$V$1001,">0") -> -0.5 | E7: =(COUNTIFS($R$2:$R$1001,$A7,$Y$2:$Y$1001,E$1,$V$2:$V$1001,">=9") - (COUNTIFS($R$2:$R$1001,$A7,$Y$2:$Y$1001,E$1,$V$2:$V$1001,"<=6"))) / COUNTIFS($R$2:$R$1001,$A7,$Y$2:$Y$1001,E$1,$V$2:$V$1001,">0") -> -0.6 | F7: =(COUNTIFS($R$2:$R$1001,$A7,$Y$2:$Y$1001,F$1,$V$2:$V$1001,">=9") - (COUNTIFS($R$2:$R$1001,$A7,$Y$2:$Y$1001,F$1,$V$2:$V$1001,"<=6"))) / COUNTIFS($R$2:$R$1001,$A7,$Y$2:$Y$1001,F$1,$V$2:$V$1001,">0") -> -0.88888889 | G7: =(COUNTIFS($R$2:$R$1001,$A7,$Y$2:$Y$1001,G$1,$V$2:$V$1001,">=9") - (COUNTIFS($R$2:$R$1001,$A7,$Y$2:$Y$1001,G$1,$V$2:$V$1001,"<=6"))) / COUNTIFS($R$2:$R$1001,$A7,$Y$2:$Y$1001,G$1,$V$2:$V$1001,">0") -> -0.375 | H7: =(COUNTIFS($R$2:$R$1001,$A7,$Y$2:$Y$1001,H$1,$V$2:$V$1001,">=9") - (COUNTIFS($R$2:$R$1001,$A7,$Y$2:$Y$1001,H$1,$V$2:$V$1001,"<=6"))) / COUNTIFS($R$2:$R$1001,$A7,$Y$2:$Y$1001,H$1,$V$2:$V$1001,">0") -> -0.66666667 | I7: =(COUNTIFS($R$2:$R$1001,$A7,$Y$2:$Y$1001,I$1,$V$2:$V$1001,">=9") - (COUNTIFS($R$2:$R$1001,$A7,$Y$2:$Y$1001,I$1,$V$2:$V$1001,"<=6"))) / COUNTIFS($R$2:$R$1001,$A7,$Y$2:$Y$1001,I$1,$V$2:$V$1001,">0") -> -0.375 | ... N7: =(COUNTIFS($R$2:$R$1001,$A7,$Y$2:$Y$1001,N$1,$V$2:$V$1001,">=9") - (COUNTIFS($R$2:$R$1001,$A7,$Y$2:$Y$1001,N$1,$V$2:$V$1001,"<=6"))) / COUNTIFS($R$2:$R$1001,$A7,$Y$2:$Y$1001,N$1,$V$2:$V$1001,">0") -> #DIV/0! | R7: Белов Алексей Константинович | S7: Егорова Алиса Михайловна | T7: 2023-10-05 | U7: 92723 | V7: 9 | W7: =MONTH(T7) -> 10 | X7: =YEAR(T7) -> 2023 | Y7: =X7&"-"&W7 -> 2023-10
A8: Петров Владимир Кириллович | B8: =(COUNTIFS($R$2:$R$1001,$A8,$Y$2:$Y$1001,B$1,$V$2:$V$1001,">=9") - (COUNTIFS($R$2:$R$1001,$A8,$Y$2:$Y$1001,B$1,$V$2:$V$1001,"<=6"))) / COUNTIFS($R$2:$R$1001,$A8,$Y$2:$Y$1001,B$1,$V$2:$V$1001,">0") -> -0.75 | C8: =(COUNTIFS($R$2:$R$1001,$A8,$Y$2:$Y$1001,C$1,$V$2:$V$1001,">=9") - (COUNTIFS($R$2:$R$1001,$A8,$Y$2:$Y$1001,C$1,$V$2:$V$1001,"<=6"))) / COUNTIFS($R$2:$R$1001,$A8,$Y$2:$Y$1001,C$1,$V$2:$V$1001,">0") -> -0.33333333 | D8: =(COUNTIFS($R$2:$R$1001,$A8,$Y$2:$Y$1001,D$1,$V$2:$V$1001,">=9") - (COUNTIFS($R$2:$R$1001,$A8,$Y$2:$Y$1001,D$1,$V$2:$V$1001,"<=6"))) / COUNTIFS($R$2:$R$1001,$A8,$Y$2:$Y$1001,D$1,$V$2:$V$1001,">0") -> -0.5 | E8: =(COUNTIFS($R$2:$R$1001,$A8,$Y$2:$Y$1001,E$1,$V$2:$V$1001,">=9") - (COUNTIFS($R$2:$R$1001,$A8,$Y$2:$Y$1001,E$1,$V$2:$V$1001,"<=6"))) / COUNTIFS($R$2:$R$1001,$A8,$Y$2:$Y$1001,E$1,$V$2:$V$1001,">0") -> 0.33333333 | F8: =(COUNTIFS($R$2:$R$1001,$A8,$Y$2:$Y$1001,F$1,$V$2:$V$1001,">=9") - (COUNTIFS($R$2:$R$1001,$A8,$Y$2:$Y$1001,F$1,$V$2:$V$1001,"<=6"))) / COUNTIFS($R$2:$R$1001,$A8,$Y$2:$Y$1001,F$1,$V$2:$V$1001,">0") -> 0 | G8: =(COUNTIFS($R$2:$R$1001,$A8,$Y$2:$Y$1001,G$1,$V$2:$V$1001,">=9") - (COUNTIFS($R$2:$R$1001,$A8,$Y$2:$Y$1001,G$1,$V$2:$V$1001,"<=6"))) / COUNTIFS($R$2:$R$1001,$A8,$Y$2:$Y$1001,G$1,$V$2:$V$1001,">0") -> -0.16666667 | H8: =(COUNTIFS($R$2:$R$1001,$A8,$Y$2:$Y$1001,H$1,$V$2:$V$1001,">=9") - (COUNTIFS($R$2:$R$1001,$A8,$Y$2:$Y$1001,H$1,$V$2:$V$1001,"<=6"))) / COUNTIFS($R$2:$R$1001,$A8,$Y$2:$Y$1001,H$1,$V$2:$V$1001,">0") -> -0.33333333 | I8: =(COUNTIFS($R$2:$R$1001,$A8,$Y$2:$Y$1001,I$1,$V$2:$V$1001,">=9") - (COUNTIFS($R$2:$R$1001,$A8,$Y$2:$Y$1001,I$1,$V$2:$V$1001,"<=6"))) / COUNTIFS($R$2:$R$1001,$A8,$Y$2:$Y$1001,I$1,$V$2:$V$1001,">0") -> -0.2 | ... N8: =(COUNTIFS($R$2:$R$1001,$A8,$Y$2:$Y$1001,N$1,$V$2:$V$1001,">=9") - (COUNTIFS($R$2:$R$1001,$A8,$Y$2:$Y$1001,N$1,$V$2:$V$1001,"<=6"))) / COUNTIFS($R$2:$R$1001,$A8,$Y$2:$Y$1001,N$1,$V$2:$V$1001,">0") -> #DIV/0! | R8: Белов Алексей Константинович | S8: Васильев Константин Дмитриевич | T8: 2023-10-09 | U8: 30795 | V8: 7 | W8: =MONTH(T8) -> 10 | X8: =YEAR(T8) -> 2023 | Y8: =X8&"-"&W8 -> 2023-10
